Workbook

Sheet نهایی
A1: OperatorID | B1: شماره پرسنلی | C1: نام و نام خانوادگی | D1: کلید مینیاتوری_مونتاژ_مونتاژ فیوز-مونتاژکامل DE-تک پل | E1: کلید مینیاتوری_چاپ_چاپ فیوز-DE-تک پل | F1: کلید مینیاتوری_بسته بندی_بسته بندی فیوز-DE-تک پل | G1: کلید مینیاتوری_بسته بندی_بسته بندی فیوز-DE-سه پل | H1: 00-كنتور MTF200F با چسب زدن_مونتاژ_ACTIVATION0 | I1: كنتور MTF200F با پورت RS با چسب زدن_مونتاژ_مونتاژ کنتور تکفاز-ساخت کارتن | J1: کنتور MTF301 با چسب زدن_مونتاژ_مونتاژ کنتور سه فاز-جوش آلتروسونیک (درپوش شفاف به درپوش اصلی) | K1: کنتور MTF301 با چسب زدن_مونتاژ_مونتاژ کنتور سه فاز-بسته بندی کنتور | L1: مونتاژ برد الکترونیکی_قطعه چینی برد الکترونیکی سه فاز دیجیتالی | M1: مونتاژ برد الکترونیکی_(تکمیل-کنترل-فریمور و برقدار کردن برد الکترونیکی کنتور سه فاز دیجیتالی | N1: پایه کنتور 117_سیم بندی ترمینال ریلی | O1: چاپ لیزر (نیم پلیت و درپوش)_چاپ درپوش باطری سه فاز با یک دستگاه | P1: چاپ لیزر (نیم پلیت و درپوش)_چاپ مشخصات ، بارکد و نام شهر با یک دستگاه | Q1: ساعتی_ساعتی-کلید مینیاتوری | R1: ساعتی_شارژر خط | S1: ساعتی_ساعتی-کنتور | T1: ساعتی_ساعتی-پایه کنتور | U1: سوپیچ قطع کن_مونتاژ قطع کن-صحه گذاری زوایای پلاتین ها | V1: سوپیچ قطع کن_مونتاژ قطع کن-مونتاژ پلاتین ها بر روی پوسته اصلی و تثبیت پلاتین ها | W1: سوپیچ قطع کن_مونتاژ قطع کن-پرس گرم | X1: سوپیچ قطع کن_مونتاژ قطع کن-هم راستایی تیغه ها (باپیچ گوشتی ) | Y1: سوپیچ قطع کن_مونتاژ قطع کن-تست استحکام پلاتین ها | Z1: سوپیچ قطع کن_مونتاژ قطع کن-مونتاژ ماگنت داخل محفظه | AA1: سوپیچ قطع کن_مونتاژ قطع کن-کالیبراسیون مونتاژ ماگنت | AB1: سوپیچ قطع کن_مونتاژ قطع کن-مونتاژ کامل بعد از اماده سازی به جز درپوش قرمز | AC1: سوپیچ قطع کن_مونتاژ قطع کن-تست شتاب | AD1: سوپیچ قطع کن_مونتاژ قطع کن-پلمپ حرارتی پایه های پوسته اصلی | AE1: سوپیچ قطع کن_مونتاژ قطع کن-تست همراستایی ،مونتاژ درپوش قرمز و بازرسی نهایی | AF1: سوپیچ قطع کن_مونتاژ قطع کن-چاپ آرم ساپکو و تاریخ تولید | AG1: سوپیچ قطع کن_مونتاژ قطع کن-بسته بندی کامل | AH1: کنتور الکترونیکی تکفاز هوشمند_مونتاژ هوشمند تکفاز-بسته بندی (شامل درپوش گذاری ترمینال و پلمپ) | AI1: کنتور الکترونیکی سه فاز هوشمند CT و CT/PT_مونتاژ هوشمندCT-بستن درپوش نیمه باز و مونتاژ باطری | AJ1: کنتور الکترونیکی سه فاز هوشمند CT و CT/PT_مونتاژ هوشمندCT-آپدیت ماژول GPRS | AK1: ساعتی_ساعتی-چاپ و بسته بندی | AL1: ساعتی_ساعتی-قطع کن سوخت | AM1: ساعتی_ساعتی-انبار | AN1: پایه کنتور 117_درپوش گذاری ترمینال | AO1: کنتور الکترونیکی سه فاز هوشمند CT و CT/PT_مونتاژ هوشمندCT-مونتاژ ترمینال بلاک منبع تغذیه و بستن پیچ ترمینال | AP1: کنتور الکترونیکی سه فاز هوشمند CT و CT/PT_مونتاژ هوشمندCT-مونتاژ برد اصلی ولحیم کاری | AQ1: کنتور الکترونیکی سه فاز هوشمند CT و CT/PT_مونتاژ هوشمندCT-لحیم پایه برد منبع تغذیه | AR1: کنتور الکترونیکی سه فاز هوشمند CT و CT/PT_مونتاژ هوشمندCT-آماده سازی محفظه(شامل برچسب و اورینگ گذاری) | AS1: کنتور الکترونیکی سه فاز هوشمند CT و CT/PT_مونتاژ هوشمندCT-جاگذاری برد اصلی و بستن پیچ | AT1: کنتور الکترونیکی سه فاز هوشمند CT و CT/PT_مونتاژ هوشمندCT-نصب Frimware | AU1: کنتور الکترونیکی سه فاز هوشمند CT و CT/PT_مونتاژ هوشمندCT-جاگذاری سیم کارت ایرانسل | AV1: پایه کنتور 118_پایه 118 با کنتور | AW1: کلید مینیاتوری_R.T.F_ چاپ RTF | AX1: کنتور الکترونیکی تکفاز هوشمند_مونتاژ کنتور هوشمند تکفاز | AY1: کنتور الکترونیکی تکفاز هوشمند_چسب ریزی و بستن درپوش | AZ1: پایه کنتور 119_پایه 119 بدون کنتور با ترمینال بلک سه پیچ و مانع سیم | BA1: ساعتی_ساعتی-تست کنتور | BB1: کنتور الکترونیکی سه فاز هوشمند DC_مونتاژ هوشمندDC-اسکن درپوش و سیم کارت | BC1: کنتور MTF301 با چسب زدن_مونتاژ_مونتاژ کنتور سه فاز-مونتاژ کامل کنتور سه فاز MTF301 | BD1: سوپیچ قطع کن_مونتاژ قطع کن-جداسازی درپوش قرمز | BE1: ساعتی_ساعتی-متفرقه_ساعتی- مونتاژ برد | BF1: ساعتی_ساعتی-تعمیر برد | BG1: ساعتی_ساعتی-خدمات پس از فروش | BH1: ساعتی_ساعتی-تست کلید مینیاتوری | BI1: کلید مینیاتوری_R.T.F_ مونتاژ RTF(4P) | BJ1: کلید مینیاتوری_R.T.F_ تست RTF(2P) | BK1: کلید مینیاتوری_R.T.F_ تست RTF(4P) | BL1: کنتور الکترونیکی سه فاز هوشمند DC_آماده سازی درپوش کنتور هوشمند DC | BM1: کنتور الکترونیکی سه فاز هوشمند DC_مونتاژ ماژول کنتور هوشمند | BN1: کلید مینیاتوری_پرچ_.....پرچ کلید مینیاتوری-تک پل | BO1: پیش مونتاژ پایه کنتور (مشترک)_.....مونتاژ کنتور هوشمند DC | BP1: پیش مونتاژ پایه کنتور (مشترک)_.....بسته بندی کنتور هوشمند سه فاز DC | BQ1: پیش مونتاژ پایه کنتور (مشترک)_..... سرسیم گذاری دو طرفه | BR1: پیش مونتاژ پایه کنتور (مشترک)_.....پرس سر سیم | BS1: پیش مونتاژ پایه کنتور (مشترک)_..... شیرینگ | BT1: پیش مونتاژ پایه کنتور (مشترک)_.....چاپ لیزر همراه با چاپ ساتپ | BU1: پیش مونتاژ پایه کنتور (مشترک)_..... چسب ریزی و بستن درپوش کنتور هوشمند سه فاز | BV1: کلید مینیاتوری_چاپ_چاپ کلید DE تک پل وارداتی | BW1: کلید مینیاتوری_چاپ_چاپ کلید DE دو پل وارداتی | BX1: کلید مینیاتوری_چاپ_چاپ کلید DE سه پل وارداتی | BY1: کلید مینیاتوری_چاپ_چاپ کلید DE چهار پل وارداتی | BZ1: کلید مینیاتوری_بسته بندی_بسته بندی کلید DE تک پل وارداتی | CA1: کلید مینیاتوری_بسته بندی_بسته بندی کلید DE دو پل وارداتی | CB1: کلید مینیاتوری_بسته بندی_بسته بندی کلید DE سه پل وارداتی | CC1: کلید مینیاتوری_بسته بندی_بسته بندی کلید DE چهار پل وارداتی | CD1: کلید مینیاتوری_بسته بندی_بسته بندی کلید RTF دو پل وارداتی | CE1: کلید مینیاتوری_بسته بندی_بسته بندی کلید RTF چهار پل وارداتی | CF1: کلید مینیاتوری_پاک کردن_پاک کردن کلید EP تک پل وارداتی | CG1: کلید مینیاتوری_پاک کردن_پاک کردن کلید EP سه پل وارداتی | CH1: کلید مینیاتوری_پاک کردن_پاک کردن کلید EP چهار پل وارداتی | CI1: کلید مینیاتوری_پاک کردن_پاک کردن کلید DE تک پل وارداتی | CJ1: کلید مینیاتوری_پاک کردن_پاک کردن کلید RTF چهار پل وارداتی | CK1: کلید مینیاتوری_باز کردن بدون پاک کردن_باز کردن بدون پاک کردن کلید DE چهار پل وارداتی | CL1: کنتور الکترونیکی سه فاز هوشمند DC_تست و برنامه ریزی کنتور | CM1: کنتور الکترونیکی تکفاز هوشمند_تست و برنامه ریزی تکفاز هوشمند 2G | CN1: پایه 121 با کنتور هوشمند تکفاز | CO1: کنتور ریلی SM120 B3_مونتاژ کنتور ریلی | CP1: کنتور ریلی SM120 B3_تست کنتور ریلی | CQ1: کنتور ریلی SM120 B3_بسته بندی کنتور ریلی | CR1: کنتور الکترونیکی سه فاز هوشمند DC_لحیم کاری و اتصال محافظ ترمینال | CS1: کنتور الکترونیکی سه فاز هوشمند DC_جوش پورت نوری | CT1: کنتور الکترونیکی سه فاز هوشمند DC_جوش محافظ ال سی دی | CU1: (غیر تعطیل)تعداد روز کار کرد | CV1: (تعطیل)تعداد روز کار کرد | CW1: میزان کارکرد | CX1: مجموع کارکرد | CY1: راندمان | CZ1: تعداد ضایعات کنتور | DA1: کسری ضایعات کنتور | DC1: بررسی
CX2: =SUM(CX4:CX84) -> 10591.709 | CY2: =SUM(CY4:CY61) -> 94.349634 | DB2: =SUM(DB4:DB84) -> 7827.9956
C3: آمار استاندارد | D3: 43 | E3: 473.7 | F3: 175 | G3: 54.16 | H3: 124.35 | I3: 40 | J3: 100 | K3: 25 | L3: 27.2 | M3: 13.6 | N3: 385 | O3: 300 | P3: 130 | Q3: 60 | R3: 60 | S3: 60 | T3: 60 | U3: 964.92 | V3: 154.8 | W3: 408.2 | X3: 385.2 | Y3: 737.3 | Z3: 434 | AA3: 119 | AB3: 74.4 | AC3: 303.1 | AD3: 456.9 | AE3: 230 | AF3: 1519 | AG3: 1846.2 | AH3: 17 | AI3: 65 | AJ3: 85 | AK3: 60 | AL3: 60 | AM3: 60 | AN3: 240 | AO3: 11 | AP3: 42 | AQ3: 33 | AR3: 93 | AS3: 65 | AT3: 92 | AU3: 97 | AV3: 13 | AW3: 179.3 | AX3: 13.5 | AY3: 47.23 | AZ3: 57 | BA3: 60 | BB3: 242 | BC3: 8.5 | BD3: 1008.4 | BE3: 60 | BF3: 60 | BG3: 60 | BH3: 60 | BI3: 5 | BJ3: 104 | BK3: 64 | BL3: 61 | BM3: 30.3 | BN3: 200 | BO3: 7.8 | BP3: 28.5 | BQ3: 291 | BR3: 1400 | BS3: 60 | BT3: 61.5 | BU3: 43.5 | BV3: 1090 | BW3: 438 | BX3: 380 | BY3: 272 | BZ3: 238 | CA3: 124 | CB3: 100 | CC3: 80 | CD3: 89 | CE3: 65 | CF3: 225 | CG3: 208 | CH3: 143 | CI3: 300 | CJ3: 60 | CK3: 454 | CL3: 0.77 | CM3: 0.97 | CN3: 12 | CO3: 18.5 | CP3: 1.45 | CQ3: 57 | CR3: 35 | CS3: 112 | CT3: 109
B4: 14226 | C4: فاطمه نیکوی دولت آبادی | M4: 253 | U4: 2800 | AA4: 360 | AB4: 8600 | AD4: 6740 | AE4: 1680 | CU4: 17 | CV4: 0 | CW4: 9640 | CX4: {=SUMPRODUCT(D4:CT4/$D$3:$CT$3)} -> 162.17728 | CY4: =CX4/CW4*100 -> 1.6823369 | CZ4: 0 | DA4: =CZ4*DA2/60 -> 0 | DB4: =CX4-DA4 -> 162.17728 | DC4: =MATCH(C4,'کارکرد اداری'!$C$3:$C$64,0) -> #N/A
B5: 14283 | C5: حسین دهقانی | S5: 7270 | BT5: 795 | CU5: 17 | CV5: 0 | CW5: 8035 | CX5: {=SUMPRODUCT(D5:CT5/$D$3:$CT$3)} -> 134.0935 | CY5: =CX5/CW5*100 -> 1.6688674 | DB5: =CX5-DA5 -> 134.0935 | DC5: =MATCH(C5,'کارکرد اداری'!$C$3:$C$64,0) -> #N/A
B6: 14329 | C6: مجید عرفانی | S6: 1400 | AP6: 21 | AR6: 301 | AS6: 195 | BO6: 172 | BT6: 4780 | BU6: 257 | CU6: 17 | CV6: 0 | CW6: 8200 | CX6: {=SUMPRODUCT(D6:CT6/$D$3:$CT$3)} -> 135.7528 | CY6: =CX6/CW6*100 -> 1.6555219 | DB6: =CX6-DA6 -> 135.7528 | DC6: =MATCH(C6,'کارکرد اداری'!$C$3:$C$64,0) -> #N/A
B7: 14328 | C7: محمدرضا احمدی | S7: 3610 | AO7: 33 | AX7: 13 | BC7: 25 | BO7: 101 | BU7: 791 | CO7: 567 | CU7: 16 | CV7: 0 | CW7: 7650 | CX7: {=SUMPRODUCT(D7:CT7/$D$3:$CT$3)} -> 128.85208 | CY7: =CX7/CW7*100 -> 1.6843409 | DB7: =CX7-DA7 -> 128.85208 | DC7: =MATCH(C7,'کارکرد اداری'!$C$3:$C$64,0) -> #N/A
B8: 14327 | C8: محمد تباهه | S8: 1210 | T8: 440 | AO8: 197 | AY8: 100 | BC8: 56 | BO8: 134 | BU8: 319 | CO8: 969 | CU8: 17 | CV8: 0 | CW8: 8020 | CX8: {=SUMPRODUCT(D8:CT8/$D$3:$CT$3)} -> 131.00582 | CY8: =CX8/CW8*100 -> 1.6334891 | DB8: =CX8-DA8 -> 131.00582 | DC8: =MATCH(C8,'کارکرد اداری'!$C$3:$C$64,0) -> #N/A
B9: 14323 | C9: علی مرادی | BA9: 30 | CL9: 105.65 | CM9: 3 | CU9: 16 | CV9: 0 | CW9: 8120 | CX9: {=SUMPRODUCT(D9:CT9/$D$3:$CT$3)} -> 140.80058 | CY9: =CX9/CW9*100 -> 1.7339972 | DB9: =CX9-DA9 -> 140.80058 | DC9: =MATCH(C9,'کارکرد اداری'!$C$3:$C$64,0) -> #N/A
B10: 14275 | C10: مهدی صبوری | D10: 274 | BF10: 620 | BH10: 8220 | CG10: 2760 | CK10: 1888 | CU10: 18 | CV10: 0 | CW10: 10300 | CX10: {=SUMPRODUCT(D10:CT10/$D$3:$CT$3)} -> 171.13325 | CY10: =CX10/CW10*100 -> 1.6614878 | DB10: =CX10-DA10 -> 171.13325 | DC10: =MATCH(C10,'کارکرد اداری'!$C$3:$C$64,0) -> #N/A
B11: 14304 | C11: مصطفی فتحی پور | Q11: 440 | BF11: 1680 | BH11: 240 | BN11: 14500 | CG11: 5417 | CK11: 5993 | CU11: 16 | CV11: 0 | CW11: 8930 | CX11: {=SUMPRODUCT(D11:CT11/$D$3:$CT$3)} -> 151.07704 | CY11: =CX11/CW11*100 -> 1.6917922 | DB11: =CX11-DA11 -> 151.07704 | DC11: =MATCH(C11,'کارکرد اداری'!$C$3:$C$64,0) -> #N/A
B12: 14331 | C12: فاطمه عالمی | D12: 4329 | M12: 424 | S12: 550 | AK12: 30 | BO12: 157 | CG12: 1940 | CU12: 17 | CV12: 0 | CW12: 10000 | CX12: {=SUMPRODUCT(D12:CT12/$D$3:$CT$3)} -> 170.97268 | CY12: =CX12/CW12*100 -> 1.7097268 | DB12: =CX12-DA12 -> 170.97268 | DC12: =MATCH(C12,'کارکرد اداری'!$C$3:$C$64,0) -> #N/A
B13: 14242 | C13: سیدسجاد مرتضوی | O13: 1200 | S13: 2820 | CU13: 7 | CV13: 0 | CW13: 3080 | CX13: {=SUMPRODUCT(D13:CT13/$D$3:$CT$3)} -> 51 | CY13: =CX13/CW13*100 -> 1.6558442 | DB13: =CX13-DA13 -> 51 | DC13: =MATCH(C13,'کارکرد اداری'!$C$3:$C$64,0) -> #N/A
B14: 14231 | C14: میترا اسکندریان | F14: 566 | G14: 171 | AK14: 1750 | BV14: 1800 | BX14: 4806 | BY14: 1555 | BZ14: 1290 | CA14: 900 | CB14: 3518 | CC14: 1965 | CU14: 15 | CV14: 0 | CW14: 7500 | CX14: {=SUMPRODUCT(D14:CT14/$D$3:$CT$3)} -> 127.99465 | CY14: =CX14/CW14*100 -> 1.7065954 | DB14: =CX14-DA14 -> 127.99465 | DC14: =MATCH(C14,'کارکرد اداری'!$C$3:$C$64,0) -> #N/A
B15: 14340 | C15: رضا جعفرپور قله زو | F15: 1461 | AJ15: 60 | AK15: 485 | AW15: 179 | BZ15: 1648 | CA15: 248 | CB15: 7519 | CC15: 3164 | CD15: 693 | CU15: 16 | CV15: 0 | CW15: 8840 | CX15: {=SUMPRODUCT(D15:CT15/$D$3:$CT$3)} -> 149.587 | CY15: =CX15/CW15*100 -> 1.6921606 | DB15: =CX15-DA15 -> 149.587 | DC15: =MATCH(C15,'کارکرد اداری'!$C$3:$C$64,0) -> #N/A
A16: 14345 | B16: 14345 | C16: حسین نعمتی | V16: 1280 | Z16: 1330 | AA16: 890 | AB16: 6299 | AC16: 12554 | AG16: 10080 | AL16: 470 | CU16: 17 | CV16: 0 | CW16: 9460 | CX16: {=SUMPRODUCT(D16:CT16/$D$3:$CT$3)} -> 158.18809 | CY16: =CX16/CW16*100 -> 1.6721785 | DB16: =CX16-DA16 -> 158.18809 | DC16: =MATCH(C16,'کارکرد اداری'!$C$3:$C$64,0) -> #N/A
A17: 14394 | B17: 14162 | C17: طیبه میامی میم | BZ17: 1800 | CB17: 4158 | CC17: 2847 | CD17: 552 | CE17: 269 | CH17: 1258 | CK17: 1000 | CU17: 12 | CV17: 0 | CW17: 6360 | CX17: {=SUMPRODUCT(D17:CT17/$D$3:$CT$3)} -> 106.07108 | CY17: =CX17/CW17*100 -> 1.6677843 | DB17: =CX17-DA17 -> 106.07108 | DC17: =MATCH(C17,'کارکرد اداری'!$C$3:$C$64,0) -> #N/A
B18: 14394 | C18: مصطفی مکرم نیا | S18: 980 | AO18: 51 | BC18: 132.5 | BO18: 490 | BU18: 893 | CO18: 211 | CU18: 17 | CV18: 0 | CW18: 8020 | CX18: {=SUMPRODUCT(D18:CT18/$D$3:$CT$3)} -> 131.31259 | CY18: =CX18/CW18*100 -> 1.637314 | DB18: =CX18-DA18 -> 131.31259 | DC18: =MATCH(C18,'کارکرد اداری'!$C$3:$C$64,0) -> #N/A
B19: 14395 | C19: مسلم سبزه کار | S19: 120 | T19: 2780 | AV19: 80 | AZ19: 300 | BM19: 560 | BP19: 33 | BS19: 710 | CQ19: 2751 | CU19: 17 | CV19: 0 | CW19: 8380 | CX19: {=SUMPRODUCT(D19:CT19/$D$3:$CT$3)} -> 139.48657 | CY19: =CX19/CW19*100 -> 1.6645176 | DB19: =CX19-DA19 -> 139.48657 | DC19: =MATCH(C19,'کارکرد اداری'!$C$3:$C$64,0) -> #N/A
B20: 14417 | C20: مریم عبدیان پور | S20: 350 | AO20: 42 | AQ20: 87 | AR20: 100 | AS20: 100 | BC20: 183.5 | BO20: 759 | CU20: 17 | CV20: 0 | CW20: 8200 | CX20: {=SUMPRODUCT(D20:CT20/$D$3:$CT$3)} -> 133.79754 | CY20: =CX20/CW20*100 -> 1.6316773 | DB20: =CX20-DA20 -> 133.79754 | DC20: =MATCH(C20,'کارکرد اداری'!$C$3:$C$64,0) -> #N/A
B21: 14396 | C21: محمد شیرازی | R21: 7660 | CU21: 14 | CV21: 0 | CW21: 7660 | CX21: {=SUMPRODUCT(D21:CT21/$D$3:$CT$3)} -> 127.66667 | CY21: =CX21/CW21*100 -> 1.6666667 | DB21: =CX21-DA21 -> 127.66667 | DC21: =MATCH(C21,'کارکرد اداری'!$C$3:$C$64,0) -> #N/A
B22: 14409 | C22: محمد روانستان | S22: 150 | T22: 60 | AH22: 36 | AV22: 91 | BC22: 93.5 | BM22: 525 | BO22: 46 | CQ22: 4420 | CU22: 16 | CV22: 0 | CW22: 7580 | CX22: {=SUMPRODUCT(D22:CT22/$D$3:$CT$3)} -> 124.38568 | CY22: =CX22/CW22*100 -> 1.640972 | DB22: =CX22-DA22 -> 124.38568 | DC22: =MATCH(C22,'کارکرد اداری'!$C$3:$C$64,0) -> #N/A
B23: 14478 | C23: مجتبی نویدی | K23: 281 | S23: 630 | T23: 260 | AV23: 52 | BM23: 60 | BP23: 817 | BS23: 120 | BU23: 254 | CA23: 1154 | CB23: 3734 | CC23: 588 | CU23: 17 | CV23: 0 | CW23: 7850 | CX23: {=SUMPRODUCT(D23:CT23/$D$3:$CT$3)} -> 122.55573 | CY23: =CX23/CW23*100 -> 1.5612195 | DB23: =CX23-DA23 -> 122.55573 | DC23: =MATCH(C23,'کارکرد اداری'!$C$3:$C$64,0) -> #N/A
B24: 14466 | C24: علی بسیج | J24: 1180 | S24: 1400 | BT24: 2132 | CS24: 6050 | CT24: 680 | CU24: 17 | CV24: 0 | CW24: 7880 | CX24: {=SUMPRODUCT(D24:CT24/$D$3:$CT$3)} -> 130.05639 | CY24: =CX24/CW24*100 -> 1.6504618 | DB24: =CX24-DA24 -> 130.05639 | DC24: =MATCH(C24,'کارکرد اداری'!$C$3:$C$64,0) -> #N/A
B25: 14531 | C25: الهه جابری | M25: 300 | BH25: 9180 | CU25: 18 | CV25: 0 | CW25: 10440 | CX25: {=SUMPRODUCT(D25:CT25/$D$3:$CT$3)} -> 175.05882 | CY25: =CX25/CW25*100 -> 1.6768087 | DB25: =CX25-DA25 -> 175.05882 | DC25: =MATCH(C25,'کارکرد اداری'!$C$3:$C$64,0) -> #N/A
B26: 14538 | C26: امیررضا عطاردی | K26: 387 | S26: 90 | T26: 210 | U26: 21000 | V26: 9955 | W26: 50 | X26: 50 | Y26: 50 | Z26: 1000 | AA26: 110 | AE26: 3360 | AL26: 60 | AV26: 255 | BP26: 320 | CU26: 17 | CV26: 0 | CW26: 9820 | CX26: {=SUMPRODUCT(D26:CT26/$D$3:$CT$3)} -> 156.55302 | CY26: =CX26/CW26*100 -> 1.5942263 | DB26: =CX26-DA26 -> 156.55302 | DC26: =MATCH(C26,'کارکرد اداری'!$C$3:$C$64,0) -> #N/A
B27: 14537 | C27: ناهید جعفریانی | M27: 394 | S27: 290 | AQ27: 464 | BC27: 49 | BF27: 440 | BO27: 535 | CO27: 108 | CU27: 17 | CV27: 0 | CW27: 8200 | CX27: {=SUMPRODUCT(D27:CT27/$D$3:$CT$3)} -> 135.39015 | CY27: =CX27/CW27*100 -> 1.6510994 | DB27: =CX27-DA27 -> 135.39015 | DC27: =MATCH(C27,'کارکرد اداری'!$C$3:$C$64,0) -> #N/A
B28: 14541 | C28: فرهاد صبوری مقدم | AF28: 3380 | AK28: 60 | AW28: 1170 | BV28: 4535 | BX28: 36867 | BY28: 14682 | CU28: 16 | CV28: 0 | CW28: 9380 | CX28: {=SUMPRODUCT(D28:CT28/$D$3:$CT$3)} -> 164.90744 | CY28: =CX28/CW28*100 -> 1.758075 | DB28: =CX28-DA28 -> 164.90744 | DC28: =MATCH(C28,'کارکرد اداری'!$C$3:$C$64,0) -> #N/A
B29: 14554 | C29: الناز فرخی | D29: 3908 | M29: 283 | Q29: 30 | CB29: 2980 | CC29: 850 | CU29: 16 | CV29: 0 | CW29: 8820 | CX29: {=SUMPRODUCT(D29:CT29/$D$3:$CT$3)} -> 152.61754 | CY29: =CX29/CW29*100 -> 1.7303576 | DB29: =CX29-DA29 -> 152.61754 | DC29: =MATCH(C29,'کارکرد اداری'!$C$3:$C$64,0) -> #N/A
B30: 14570 | C30: اکرم ریحانی | D30: 4300 | M30: 424 | Q30: 30 | CB30: 4183 | CU30: 17 | CV30: 0 | CW30: 10000 | CX30: {=SUMPRODUCT(D30:CT30/$D$3:$CT$3)} -> 173.50647 | CY30: =CX30/CW30*100 -> 1.7350647 | DB30: =CX30-DA30 -> 173.50647 | DC30: =MATCH(C30,'کارکرد اداری'!$C$3:$C$64,0) -> #N/A
B31: 14580 | C31: عادل آخریان | S31: 1660 | AI31: 150 | AU31: 563 | BB31: 250 | BC31: 196.5 | BO31: 541.5 | CU31: 17 | CV31: 0 | CW31: 7870 | CX31: {=SUMPRODUCT(D31:CT31/$D$3:$CT$3)} -> 129.35226 | CY31: =CX31/CW31*100 -> 1.643612 | DB31: =CX31-DA31 -> 129.35226 | DC31: =MATCH(C31,'کارکرد اداری'!$C$3:$C$64,0) -> #N/A
B32: 14592 | C32: ندا ذکاوتی | BJ32: 5890 | BK32: 5072 | CG32: 540 | CH32: 40 | CU32: 15 | CV32: 0 | CW32: 8460 | CX32: {=SUMPRODUCT(D32:CT32/$D$3:$CT$3)} -> 138.76049 | CY32: =CX32/CW32*100 -> 1.6401949 | DB32: =CX32-DA32 -> 138.76049 | DC32: =MATCH(C32,'کارکرد اداری'!$C$3:$C$64,0) -> #N/A
B33: 14603 | C33: حجت دشتی | M33: 253 | S33: 1600 | BC33: 40 | BO33: 68 | CG33: 900 | CH33: 1258 | CK33: 3851 | CO33: 492 | CR33: 192 | CU33: 16 | CV33: 0 | CW33: 7370 | CX33: {=SUMPRODUCT(D33:CT33/$D$3:$CT$3)} -> 112.38025 | CY33: =CX33/CW33*100 -> 1.5248338 | DB33: =CX33-DA33 -> 112.38025 | DC33: =MATCH(C33,'کارکرد اداری'!$C$3:$C$64,0) -> #N/A
B34: 14140 | C34: مرضیه تقوی کمال آبادی | M34: 394 | BF34: 3800 | BG34: 5220 | CU34: 19 | CV34: 0 | CW34: 10700 | CX34: {=SUMPRODUCT(D34:CT34/$D$3:$CT$3)} -> 179.30392 | CY34: =CX34/CW34*100 -> 1.6757376 | DB34: =CX34-DA34 -> 179.30392 | DC34: =MATCH(C34,'کارکرد اداری'!$C$3:$C$64,0) -> #N/A
B35: 14546 | C35: اسماعیل مقدسی | K35: 649 | S35: 350 | T35: 300 | AM35: 120 | AV35: 250 | BM35: 475 | BP35: 1018 | BS35: 294 | CU35: 16 | CV35: 0 | CW35: 7760 | CX35: {=SUMPRODUCT(D35:CT35/$D$3:$CT$3)} -> 114.31997 | CY35: =CX35/CW35*100 -> 1.4731955 | DB35: =CX35-DA35 -> 114.31997 | DC35: =MATCH(C35,'کارکرد اداری'!$C$3:$C$64,0) -> #N/A
B36: 14631 | C36: علی حسنی | BA36: 30 | BC36: 56 | BM36: 220 | BU36: 129 | CL36: 16.96 | CM36: 4 | CO36: 225 | CP36: 112 | CU36: 17 | CV36: 0 | CW36: 7940 | CX36: {=SUMPRODUCT(D36:CT36/$D$3:$CT$3)} -> 132.86771 | CY36: =CX36/CW36*100 -> 1.6733968 | DB36: =CX36-DA36 -> 132.86771 | DC36: =MATCH(C36,'کارکرد اداری'!$C$3:$C$64,0) -> #N/A
B37: 14636 | C37: مریم مهربان | D37: 4177 | L37: 636 | Q37: 30 | S37: 30 | BO37: 18 | CG37: 2000 | CO37: 500 | CU37: 17 | CV37: 0 | CW37: 9750 | CX37: {=SUMPRODUCT(D37:CT37/$D$3:$CT$3)} -> 160.47199 | CY37: =CX37/CW37*100 -> 1.6458666 | DB37: =CX37-DA37 -> 160.47199 | DC37: =MATCH(C37,'کارکرد اداری'!$C$3:$C$64,0) -> #N/A
B38: 14641 | C38: مجید شاهین فر | I38: 185 | N38: 600 | S38: 240 | T38: 500 | AN38: 600 | BL38: 3312 | BQ38: 900 | BS38: 1130 | CG38: 360 | CH38: 1365 | CK38: 1273 | CU38: 17 | CV38: 0 | CW38: 7840 | CX38: {=SUMPRODUCT(D38:CT38/$D$3:$CT$3)} -> 111.31816 | CY38: =CX38/CW38*100 -> 1.4198745 | DB38: =CX38-DA38 -> 111.31816 | DC38: =MATCH(C38,'کارکرد اداری'!$C$3:$C$64,0) -> #N/A
B39: 14642 | C39: سیدحسین جعفری | S39: 800 | BC39: 197.5 | BO39: 192 | BU39: 494 | CO39: 1128 | CU39: 17 | CV39: 0 | CW39: 8200 | CX39: {=SUMPRODUCT(D39:CT39/$D$3:$CT$3)} -> 133.51331 | CY39: =CX39/CW39*100 -> 1.6282111 | DB39: =CX39-DA39 -> 133.51331 | DC39: =MATCH(C39,'کارکرد اداری'!$C$3:$C$64,0) -> #N/A
B40: 784 | C40: علیرضا زاهدی اره | BA40: 50 | CL40: 98.4 | CP40: 10.65 | CU40: 17 | CV40: 0 | CW40: 7880 | CX40: {=SUMPRODUCT(D40:CT40/$D$3:$CT$3)} -> 135.97037 | CY40: =CX40/CW40*100 -> 1.7255123 | DB40: =CX40-DA40 -> 135.97037 | DC40: =MATCH(C40,'کارکرد اداری'!$C$3:$C$64,0) -> #N/A
...

Sheet خلاصه عملکرد
A1: ماه : | B1: شهریور 1403 | E1: تعداد روز ماه : | F1: 31 | H1: تعداد روزهای تعطیل ماه (با احتساب جمعه ها) : | M1: 10
A2: وضعیت | B2: محل فعالیت | C2: شماره کارت | D2: شماره پرسنلی | E2: نام و نام خانوادگی | F2: نام و نام خانوادگی2 | G2: غیبت | H2: بیماری | I2: مرخصی بدون حقوق | J2: مرخصی استحقاقی | K2: ساعت مرخصی | L2: دقیقه مرخصی | M2: ساعت اضافه کار | N2: دقیقه اضافه کار | O2: تعداد روز کاری (غیر تعطیل) | P2: حضور اداری | Q2: حضور ثبت شده واحد برنامه ریزی | R2: تفاوت حضور اداری و برنامه ریزی | S2: کارکرد آماری | T2: کسر کار | U2: پاداش | V2: کسر کار (اداری) | W2: پاداش (اداری) | X2: کسر کار طبق محاسبات صنایع | Y2: پاداش طبق محاسبات صنایع | Z2: شماره کارت | AA2: شماره پرسنلی | AB2: توضیحات
C3: 1097 | D3: 14345 | E3: حسین نعمتی | G3: =_xlfn.IFNA(_xlfn.XLOOKUP(D3,'کارکرد اداری'!$C$4:$C$204,'کارکرد اداری'!$N$4:$N$204,"0",0),_xlfn.XLOOKUP(C3,'کارکرد اداری'!$C$4:$C$204,'کارکرد اداری'!$N$4:$N$204,"0",0)) -> 0 | H3: =_xlfn.XLOOKUP(D3,'کارکرد اداری'!$C$4:$C$204,'کارکرد اداری'!$K$4:$K$204,0,0) -> 0 | I3: =_xlfn.XLOOKUP(D3,'کارکرد اداری'!$C$4:$C$204,'کارکرد اداری'!$I$4:$I$204,0,0) -> 0 | J3: {=_xlfn.IFNA(INDEX('کارکرد اداری'!J:J,MATCH(C3,'کارکرد اداری'!B:B,0),0),INDEX('کارکرد اداری'!J:J,MATCH(D3,'کارکرد اداری'!C:C,0),0))} -> #N/A | K3: {=_xlfn.IFNA(INDEX('کارکرد اداری'!R:R,MATCH(C3,'کارکرد اداری'!B:B,0),0),INDEX('کارکرد اداری'!R:R,MATCH(D3,'کارکرد اداری'!C:C,0),0))} -> #N/A | L3: {=_xlfn.IFNA(INDEX('کارکرد اداری'!S:S,MATCH(C3,'کارکرد اداری'!B:B,0),0),INDEX('کارکرد اداری'!S:S,MATCH(D3,'کارکرد اداری'!C:C,0),0))} -> #N/A | M3: {=_xlfn.IFNA(INDEX('کارکرد اداری'!P:P,MATCH(C3,'کارکرد اداری'!B:B,0),0),INDEX('کارکرد اداری'!P:P,MATCH(D3,'کارکرد اداری'!C:C,0),0))} -> #N/A | N3: {=_xlfn.IFNA(INDEX('کارکرد اداری'!Q:Q,MATCH(C3,'کارکرد اداری'!B:B,0),0),INDEX('کارکرد اداری'!Q:Q,MATCH(D3,'کارکرد اداری'!C:C,0),0))} -> #N/A | O3: =$F$1-$M$1-G3-H3-I3-J3 -> #N/A | P3: =((O3*440+M3*60+N3)-(K3*60-L3))/60 -> #N/A | Q3: {=_xlfn.IFNA(INDEX(نهایی!CW:CW,MATCH(D3,نهایی!B:B,0),0)/60,INDEX(نهایی!CW:CW,MATCH(C3,نهایی!B:B,0),0)/60)} -> 157.66667 | R3: =Q3-P3 -> #N/A | S3: =_xlfn.IFNA(INDEX(نهایی!CX:CX,MATCH(D3,نهایی!B:B,0)),INDEX(نهایی!CX:CX,MATCH(C3,نهایی!B:B,0))) -> 158.18809 | T3: =IF(S3>Q3,"",Q3-S3) | U3: =IF(Q3>S3,"",S3-Q3) -> 0.52142395 | V3: =IF(P3>S3,P3-S3,"") -> #N/A | W3: =IF(P3<S3,S3-P3,"") -> #N/A | X3: =ROUNDDOWN(IF((0.95-S3/P3)>0,(0.95-S3/P3),0)*Q3,0) -> #N/A | Y3: =ROUNDUP((IF(((S3/P3)-0.97)>0,((S3/P3)-0.97),0)*Q3)/1,0) -> #N/A | Z3: =VLOOKUP(C3,نهایی!B:B,1,0) -> #N/A | AA3: =VLOOKUP(D3,نهایی!B:B,1,0) -> 14345
C4: =_xlfn.XLOOKUP(D4,'کارکرد اداری'!$C$3:$C$106,'کارکرد اداری'!$B$3:$B$106,0,1) -> 602 | D4: 14541 | E4: فرهاد صبوری مقدم | G4: =_xlfn.IFNA(_xlfn.XLOOKUP(D4,'کارکرد اداری'!$C$4:$C$204,'کارکرد اداری'!$N$4:$N$204,"0",0),_xlfn.XLOOKUP(C4,'کارکرد اداری'!$C$4:$C$204,'کارکرد اداری'!$N$4:$N$204,"0",0)) -> 0 | H4: =_xlfn.XLOOKUP(D4,'کارکرد اداری'!$C$4:$C$204,'کارکرد اداری'!$K$4:$K$204,0,1) -> 0 | I4: =_xlfn.XLOOKUP(D4,'کارکرد اداری'!$C$4:$C$204,'کارکرد اداری'!$I$4:$I$204,0,1) -> 0 | J4: {=_xlfn.IFNA(INDEX('کارکرد اداری'!J:J,MATCH(C4,'کارکرد اداری'!B:B,0),0),INDEX('کارکرد اداری'!J:J,MATCH(D4,'کارکرد اداری'!C:C,0),0))} -> #N/A | K4: {=_xlfn.IFNA(INDEX('کارکرد اداری'!R:R,MATCH(C4,'کارکرد اداری'!B:B,0),0),INDEX('کارکرد اداری'!R:R,MATCH(D4,'کارکرد اداری'!C:C,0),0))} -> #N/A | L4: {=_xlfn.IFNA(INDEX('کارکرد اداری'!S:S,MATCH(C4,'کارکرد اداری'!B:B,0),0),INDEX('کارکرد اداری'!S:S,MATCH(D4,'کارکرد اداری'!C:C,0),0))} -> #N/A | M4: {=_xlfn.IFNA(INDEX('کارکرد اداری'!P:P,MATCH(C4,'کارکرد اداری'!B:B,0),0),INDEX('کارکرد اداری'!P:P,MATCH(D4,'کارکرد اداری'!C:C,0),0))} -> #N/A | N4: {=_xlfn.IFNA(INDEX('کارکرد اداری'!Q:Q,MATCH(C4,'کارکرد اداری'!B:B,0),0),INDEX('کارکرد اداری'!Q:Q,MATCH(D4,'کارکرد اداری'!C:C,0),0))} -> #N/A | O4: =$F$1-$M$1-G4-H4-I4-J4 -> #N/A | P4: =((O4*440+M4*60+N4)-(K4*60-L4))/60 -> #N/A | Q4: {=_xlfn.IFNA(INDEX(نهایی!CW:CW,MATCH(D4,نهایی!B:B,0),0)/60,INDEX(نهایی!CW:CW,MATCH(C4,نهایی!B:B,0),0)/60)} -> 156.33333 | R4: =Q4-P4 -> #N/A | S4: =_xlfn.IFNA(INDEX(نهایی!CX:CX,MATCH(D4,نهایی!B:B,0)),INDEX(نهایی!CX:CX,MATCH(C4,نهایی!B:B,0))) -> 164.90744 | T4: =IF(S4>Q4,"",Q4-S4) | U4: =IF(Q4>S4,"",S4-Q4) -> 8.5741039 | V4: =IF(P4>S4,P4-S4,"") -> #N/A | W4: =IF(P4<S4,S4-P4,"") -> #N/A | X4: =ROUNDDOWN(IF((0.95-S4/P4)>0,(0.95-S4/P4),0)*Q4,0) -> #N/A | Y4: =ROUNDUP((IF(((S4/P4)-0.97)>0,((S4/P4)-0.97),0)*Q4)/1,0) -> #N/A | Z4: =VLOOKUP(C4,نهایی!B:B,1,0) -> #N/A | AA4: =VLOOKUP(D4,نهایی!B:B,1,0) -> 14541
C5: =_xlfn.XLOOKUP(D5,'کارکرد اداری'!$C$3:$C$106,'کارکرد اداری'!$B$3:$B$106,0,1) -> 580 | D5: 14531 | E5: الهه جابری | G5: =_xlfn.IFNA(_xlfn.XLOOKUP(D5,'کارکرد اداری'!$C$4:$C$204,'کارکرد اداری'!$N$4:$N$204,"0",0),_xlfn.XLOOKUP(C5,'کارکرد اداری'!$C$4:$C$204,'کارکرد اداری'!$N$4:$N$204,"0",0)) -> 0 | H5: =_xlfn.XLOOKUP(D5,'کارکرد اداری'!$C$4:$C$204,'کارکرد اداری'!$K$4:$K$204,0,1) -> 0 | I5: =_xlfn.XLOOKUP(D5,'کارکرد اداری'!$C$4:$C$204,'کارکرد اداری'!$I$4:$I$204,0,1) -> 0 | J5: {=_xlfn.IFNA(INDEX('کارکرد اداری'!J:J,MATCH(C5,'کارکرد اداری'!B:B,0),0),INDEX('کارکرد اداری'!J:J,MATCH(D5,'کارکرد اداری'!C:C,0),0))} -> #N/A | K5: {=_xlfn.IFNA(INDEX('کارکرد اداری'!R:R,MATCH(C5,'کارکرد اداری'!B:B,0),0),INDEX('کارکرد اداری'!R:R,MATCH(D5,'کارکرد اداری'!C:C,0),0))} -> #N/A | L5: {=_xlfn.IFNA(INDEX('کارکرد اداری'!S:S,MATCH(C5,'کارکرد اداری'!B:B,0),0),INDEX('کارکرد اداری'!S:S,MATCH(D5,'کارکرد اداری'!C:C,0),0))} -> #N/A | M5: {=_xlfn.IFNA(INDEX('کارکرد اداری'!P:P,MATCH(C5,'کارکرد اداری'!B:B,0),0),INDEX('کارکرد اداری'!P:P,MATCH(D5,'کارکرد اداری'!C:C,0),0))} -> #N/A | N5: {=_xlfn.IFNA(INDEX('کارکرد اداری'!Q:Q,MATCH(C5,'کارکرد اداری'!B:B,0),0),INDEX('کارکرد اداری'!Q:Q,MATCH(D5,'کارکرد اداری'!C:C,0),0))} -> #N/A | O5: =$F$1-$M$1-G5-H5-I5-J5 -> #N/A | P5: =((O5*440+M5*60+N5)-(K5*60-L5))/60 -> #N/A | Q5: {=_xlfn.IFNA(INDEX(نهایی!CW:CW,MATCH(D5,نهایی!B:B,0),0)/60,INDEX(نهایی!CW:CW,MATCH(C5,نهایی!B:B,0),0)/60)} -> 174 | R5: =Q5-P5 -> #N/A | S5: =_xlfn.IFNA(INDEX(نهایی!CX:CX,MATCH(D5,نهایی!B:B,0)),INDEX(نهایی!CX:CX,MATCH(C5,نهایی!B:B,0))) -> 175.05882 | T5: =IF(S5>Q5,"",Q5-S5) | U5: =IF(Q5>S5,"",S5-Q5) -> 1.0588235 | V5: =IF(P5>S5,P5-S5,"") -> #N/A | W5: =IF(P5<S5,S5-P5,"") -> #N/A | X5: =ROUNDDOWN(IF((0.95-S5/P5)>0,(0.95-S5/P5),0)*Q5,0) -> #N/A | Y5: =ROUNDUP((IF(((S5/P5)-0.97)>0,((S5/P5)-0.97),0)*Q5)/1,0) -> #N/A | Z5: =VLOOKUP(C5,نهایی!B:B,1,0) -> #N/A | AA5: =VLOOKUP(D5,نهایی!B:B,1,0) -> 14531
C6: =_xlfn.XLOOKUP(D6,'کارکرد اداری'!$C$3:$C$106,'کارکرد اداری'!$B$3:$B$106,0,1) -> 644 | D6: 14570 | E6: اکرم ریحانی | G6: =_xlfn.IFNA(_xlfn.XLOOKUP(D6,'کارکرد اداری'!$C$4:$C$204,'کارکرد اداری'!$N$4:$N$204,"0",0),_xlfn.XLOOKUP(C6,'کارکرد اداری'!$C$4:$C$204,'کارکرد اداری'!$N$4:$N$204,"0",0)) -> 0 | H6: =_xlfn.XLOOKUP(D6,'کارکرد اداری'!$C$4:$C$204,'کارکرد اداری'!$K$4:$K$204,0,1) -> 0 | I6: =_xlfn.XLOOKUP(D6,'کارکرد اداری'!$C$4:$C$204,'کارکرد اداری'!$I$4:$I$204,0,1) -> 0 | J6: {=_xlfn.IFNA(INDEX('کارکرد اداری'!J:J,MATCH(C6,'کارکرد اداری'!B:B,0),0),INDEX('کارکرد اداری'!J:J,MATCH(D6,'کارکرد اداری'!C:C,0),0))} -> #N/A | K6: {=_xlfn.IFNA(INDEX('کارکرد اداری'!R:R,MATCH(C6,'کارکرد اداری'!B:B,0),0),INDEX('کارکرد اداری'!R:R,MATCH(D6,'کارکرد اداری'!C:C,0),0))} -> #N/A | L6: {=_xlfn.IFNA(INDEX('کارکرد اداری'!S:S,MATCH(C6,'کارکرد اداری'!B:B,0),0),INDEX('کارکرد اداری'!S:S,MATCH(D6,'کارکرد اداری'!C:C,0),0))} -> #N/A | M6: {=_xlfn.IFNA(INDEX('کارکرد اداری'!P:P,MATCH(C6,'کارکرد اداری'!B:B,0),0),INDEX('کارکرد اداری'!P:P,MATCH(D6,'کارکرد اداری'!C:C,0),0))} -> #N/A | N6: {=_xlfn.IFNA(INDEX('کارکرد اداری'!Q:Q,MATCH(C6,'کارکرد اداری'!B:B,0),0),INDEX('کارکرد اداری'!Q:Q,MATCH(D6,'کارکرد اداری'!C:C,0),0))} -> #N/A | O6: =$F$1-$M$1-G6-H6-I6-J6 -> #N/A | P6: =((O6*440+M6*60+N6)-(K6*60-L6))/60 -> #N/A | Q6: {=_xlfn.IFNA(INDEX(نهایی!CW:CW,MATCH(D6,نهایی!B:B,0),0)/60,INDEX(نهایی!CW:CW,MATCH(C6,نهایی!B:B,0),0)/60)} -> 166.66667 | R6: =Q6-P6 -> #N/A | S6: =_xlfn.IFNA(INDEX(نهایی!CX:CX,MATCH(D6,نهایی!B:B,0)),INDEX(نهایی!CX:CX,MATCH(C6,نهایی!B:B,0))) -> 173.50647 | T6: =IF(S6>Q6,"",Q6-S6) | U6: =IF(Q6>S6,"",S6-Q6) -> 6.8398039 | V6: =IF(P6>S6,P6-S6,"") -> #N/A | W6: =IF(P6<S6,S6-P6,"") -> #N/A | X6: =ROUNDDOWN(IF((0.95-S6/P6)>0,(0.95-S6/P6),0)*Q6,0) -> #N/A | Y6: =ROUNDUP((IF(((S6/P6)-0.97)>0,((S6/P6)-0.97),0)*Q6)/1,0) -> #N/A | Z6: =VLOOKUP(C6,نهایی!B:B,1,0) -> #N/A | AA6: =VLOOKUP(D6,نهایی!B:B,1,0) -> 14570
C7: =_xlfn.XLOOKUP(D7,'کارکرد اداری'!$C$3:$C$106,'کارکرد اداری'!$B$3:$B$106,0,1) -> 1015 | D7: 1015 | E7: صدیقه نامجو گوش | G7: =_xlfn.IFNA(_xlfn.XLOOKUP(D7,'کارکرد اداری'!$C$4:$C$204,'کارکرد اداری'!$N$4:$N$204,"0",0),_xlfn.XLOOKUP(C7,'کارکرد اداری'!$C$4:$C$204,'کارکرد اداری'!$N$4:$N$204,"0",0)) -> #N/A | H7: =_xlfn.XLOOKUP(D7,'کارکرد اداری'!$C$4:$C$204,'کارکرد اداری'!$K$4:$K$204,0,1) -> 0 | I7: =_xlfn.XLOOKUP(D7,'کارکرد اداری'!$C$4:$C$204,'کارکرد اداری'!$I$4:$I$204,0,1) -> 0 | J7: {=_xlfn.IFNA(INDEX('کارکرد اداری'!J:J,MATCH(C7,'کارکرد اداری'!B:B,0),0),INDEX('کارکرد اداری'!J:J,MATCH(D7,'کارکرد اداری'!C:C,0),0))} -> #N/A | K7: {=_xlfn.IFNA(INDEX('کارکرد اداری'!R:R,MATCH(C7,'کارکرد اداری'!B:B,0),0),INDEX('کارکرد اداری'!R:R,MATCH(D7,'کارکرد اداری'!C:C,0),0))} -> #N/A | L7: {=_xlfn.IFNA(INDEX('کارکرد اداری'!S:S,MATCH(C7,'کارکرد اداری'!B:B,0),0),INDEX('کارکرد اداری'!S:S,MATCH(D7,'کارکرد اداری'!C:C,0),0))} -> #N/A | M7: {=_xlfn.IFNA(INDEX('کارکرد اداری'!P:P,MATCH(C7,'کارکرد اداری'!B:B,0),0),INDEX('کارکرد اداری'!P:P,MATCH(D7,'کارکرد اداری'!C:C,0),0))} -> #N/A | N7: {=_xlfn.IFNA(INDEX('کارکرد اداری'!Q:Q,MATCH(C7,'کارکرد اداری'!B:B,0),0),INDEX('کارکرد اداری'!Q:Q,MATCH(D7,'کارکرد اداری'!C:C,0),0))} -> #N/A | O7: =$F$1-$M$1-G7-H7-I7-J7 -> #N/A | P7: =((O7*440+M7*60+N7)-(K7*60-L7))/60 -> #N/A | Q7: {=_xlfn.IFNA(INDEX(نهایی!CW:CW,MATCH(D7,نهایی!B:B,0),0)/60,INDEX(نهایی!CW:CW,MATCH(C7,نهایی!B:B,0),0)/60)} -> 154.66667 | R7: =Q7-P7 -> #N/A | S7: =_xlfn.IFNA(INDEX(نهایی!CX:CX,MATCH(D7,نهایی!B:B,0)),INDEX(نهایی!CX:CX,MATCH(C7,نهایی!B:B,0))) -> 161.70931 | T7: =IF(S7>Q7,"",Q7-S7) | U7: =IF(Q7>S7,"",S7-Q7) -> 7.0426448 | V7: =IF(P7>S7,P7-S7,"") -> #N/A | W7: =IF(P7<S7,S7-P7,"") -> #N/A | X7: =ROUNDDOWN(IF((0.95-S7/P7)>0,(0.95-S7/P7),0)*Q7,0) -> #N/A | Y7: =ROUNDUP((IF(((S7/P7)-0.97)>0,((S7/P7)-0.97),0)*Q7)/1,0) -> #N/A | Z7: =VLOOKUP(C7,نهایی!B:B,1,0) -> 1015 | AA7: =VLOOKUP(D7,نهایی!B:B,1,0) -> 1015
A8: آموزشی | C8: 1163 | D8: 1163 | E8: مهدی بقائی مقدم | G8: =_xlfn.IFNA(_xlfn.XLOOKUP(D8,'کارکرد اداری'!$C$4:$C$204,'کارکرد اداری'!$N$4:$N$204,"0",0),_xlfn.XLOOKUP(C8,'کارکرد اداری'!$C$4:$C$204,'کارکرد اداری'!$N$4:$N$204,"0",0)) -> #N/A | H8: =_xlfn.XLOOKUP(D8,'کارکرد اداری'!$C$4:$C$204,'کارکرد اداری'!$K$4:$K$204,0,1) -> 0 | I8: =_xlfn.XLOOKUP(D8,'کارکرد اداری'!$C$4:$C$204,'کارکرد اداری'!$I$4:$I$204,0,1) -> 0 | J8: {=_xlfn.IFNA(INDEX('کارکرد اداری'!J:J,MATCH(C8,'کارکرد اداری'!B:B,0),0),INDEX('کارکرد اداری'!J:J,MATCH(D8,'کارکرد اداری'!C:C,0),0))} -> #N/A | K8: {=_xlfn.IFNA(INDEX('کارکرد اداری'!R:R,MATCH(C8,'کارکرد اداری'!B:B,0),0),INDEX('کارکرد اداری'!R:R,MATCH(D8,'کارکرد اداری'!C:C,0),0))} -> #N/A | L8: {=_xlfn.IFNA(INDEX('کارکرد اداری'!S:S,MATCH(C8,'کارکرد اداری'!B:B,0),0),INDEX('کارکرد اداری'!S:S,MATCH(D8,'کارکرد اداری'!C:C,0),0))} -> #N/A | M8: {=_xlfn.IFNA(INDEX('کارکرد اداری'!P:P,MATCH(C8,'کارکرد اداری'!B:B,0),0),INDEX('کارکرد اداری'!P:P,MATCH(D8,'کارکرد اداری'!C:C,0),0))} -> #N/A | N8: {=_xlfn.IFNA(INDEX('کارکرد اداری'!Q:Q,MATCH(C8,'کارکرد اداری'!B:B,0),0),INDEX('کارکرد اداری'!Q:Q,MATCH(D8,'کارکرد اداری'!C:C,0),0))} -> #N/A | O8: =$F$1-$M$1-G8-H8-I8-J8 -> #N/A | P8: =((O8*440+M8*60+N8)-(K8*60-L8))/60 -> #N/A | Q8: {=_xlfn.IFNA(INDEX(نهایی!CW:CW,MATCH(D8,نهایی!B:B,0),0)/60,INDEX(نهایی!CW:CW,MATCH(C8,نهایی!B:B,0),0)/60)} -> 139.66667 | R8: =Q8-P8 -> #N/A | S8: =_xlfn.IFNA(INDEX(نهایی!CX:CX,MATCH(D8,نهایی!B:B,0)),INDEX(نهایی!CX:CX,MATCH(C8,نهایی!B:B,0))) -> 145.39582 | T8: =IF(S8>Q8,"",Q8-S8) | U8: =IF(Q8>S8,"",S8-Q8) -> 5.7291486 | V8: =IF(P8>S8,P8-S8,"") -> #N/A | W8: =IF(P8<S8,S8-P8,"") -> #N/A | X8: =ROUNDDOWN(IF((0.95-S8/P8)>0,(0.95-S8/P8),0)*Q8,0) -> #N/A | Y8: =ROUNDUP((IF(((S8/P8)-0.97)>0,((S8/P8)-0.97),0)*Q8)/1,0) -> #N/A | Z8: =VLOOKUP(C8,نهایی!B:B,1,0) -> 1163 | AA8: =VLOOKUP(D8,نهایی!B:B,1,0) -> 1163
C9: =_xlfn.XLOOKUP(D9,'کارکرد اداری'!$C$3:$C$106,'کارکرد اداری'!$B$3:$B$106,0,1) -> 245 | D9: 14275 | E9: مهدی صبوری | G9: =_xlfn.IFNA(_xlfn.XLOOKUP(D9,'کارکرد اداری'!$C$4:$C$204,'کارکرد اداری'!$N$4:$N$204,"0",0),_xlfn.XLOOKUP(C9,'کارکرد اداری'!$C$4:$C$204,'کارکرد اداری'!$N$4:$N$204,"0",0)) -> 0 | H9: =_xlfn.XLOOKUP(D9,'کارکرد اداری'!$C$4:$C$204,'کارکرد اداری'!$K$4:$K$204,0,1) -> 0 | I9: =_xlfn.XLOOKUP(D9,'کارکرد اداری'!$C$4:$C$204,'کارکرد اداری'!$I$4:$I$204,0,1) -> 0 | J9: {=_xlfn.IFNA(INDEX('کارکرد اداری'!J:J,MATCH(C9,'کارکرد اداری'!B:B,0),0),INDEX('کارکرد اداری'!J:J,MATCH(D9,'کارکرد اداری'!C:C,0),0))} -> #N/A | K9: {=_xlfn.IFNA(INDEX('کارکرد اداری'!R:R,MATCH(C9,'کارکرد اداری'!B:B,0),0),INDEX('کارکرد اداری'!R:R,MATCH(D9,'کارکرد اداری'!C:C,0),0))} -> #N/A | L9: {=_xlfn.IFNA(INDEX('کارکرد اداری'!S:S,MATCH(C9,'کارکرد اداری'!B:B,0),0),INDEX('کارکرد اداری'!S:S,MATCH(D9,'کارکرد اداری'!C:C,0),0))} -> #N/A | M9: {=_xlfn.IFNA(INDEX('کارکرد اداری'!P:P,MATCH(C9,'کارکرد اداری'!B:B,0),0),INDEX('کارکرد اداری'!P:P,MATCH(D9,'کارکرد اداری'!C:C,0),0))} -> #N/A | N9: {=_xlfn.IFNA(INDEX('کارکرد اداری'!Q:Q,MATCH(C9,'کارکرد اداری'!B:B,0),0),INDEX('کارکرد اداری'!Q:Q,MATCH(D9,'کارکرد اداری'!C:C,0),0))} -> #N/A | O9: =$F$1-$M$1-G9-H9-I9-J9 -> #N/A | P9: =((O9*440+M9*60+N9)-(K9*60-L9))/60 -> #N/A | Q9: {=_xlfn.IFNA(INDEX(نهایی!CW:CW,MATCH(D9,نهایی!B:B,0),0)/60,INDEX(نهایی!CW:CW,MATCH(C9,نهایی!B:B,0),0)/60)} -> 171.66667 | R9: =Q9-P9 -> #N/A | S9: =_xlfn.IFNA(INDEX(نهایی!CX:CX,MATCH(D9,نهایی!B:B,0)),INDEX(نهایی!CX:CX,MATCH(C9,نهایی!B:B,0))) -> 171.13325 | T9: =IF(S9>Q9,"",Q9-S9) -> 0.53341923 | U9: =IF(Q9>S9,"",S9-Q9) | V9: =IF(P9>S9,P9-S9,"") -> #N/A | W9: =IF(P9<S9,S9-P9,"") -> #N/A | X9: =ROUNDDOWN(IF((0.95-S9/P9)>0,(0.95-S9/P9),0)*Q9,0) -> #N/A | Y9: =ROUNDUP((IF(((S9/P9)-0.97)>0,((S9/P9)-0.97),0)*Q9)/1,0) -> #N/A | Z9: =VLOOKUP(C9,نهایی!B:B,1,0) -> #N/A | AA9: =VLOOKUP(D9,نهایی!B:B,1,0) -> 14275
C10: =_xlfn.XLOOKUP(D10,'کارکرد اداری'!$C$3:$C$106,'کارکرد اداری'!$B$3:$B$106,0,1) -> 1013 | D10: 14760 | E10: فرامرز نظرپور | G10: =_xlfn.IFNA(_xlfn.XLOOKUP(D10,'کارکرد اداری'!$C$4:$C$204,'کارکرد اداری'!$N$4:$N$204,"0",0),_xlfn.XLOOKUP(C10,'کارکرد اداری'!$C$4:$C$204,'کارکرد اداری'!$N$4:$N$204,"0",0)) -> 0 | H10: =_xlfn.XLOOKUP(D10,'کارکرد اداری'!$C$4:$C$204,'کارکرد اداری'!$K$4:$K$204,0,1) -> 0 | I10: =_xlfn.XLOOKUP(D10,'کارکرد اداری'!$C$4:$C$204,'کارکرد اداری'!$I$4:$I$204,0,1) -> 0 | J10: {=_xlfn.IFNA(INDEX('کارکرد اداری'!J:J,MATCH(C10,'کارکرد اداری'!B:B,0),0),INDEX('کارکرد اداری'!J:J,MATCH(D10,'کارکرد اداری'!C:C,0),0))} -> #N/A | K10: {=_xlfn.IFNA(INDEX('کارکرد اداری'!R:R,MATCH(C10,'کارکرد اداری'!B:B,0),0),INDEX('کارکرد اداری'!R:R,MATCH(D10,'کارکرد اداری'!C:C,0),0))} -> #N/A | L10: {=_xlfn.IFNA(INDEX('کارکرد اداری'!S:S,MATCH(C10,'کارکرد اداری'!B:B,0),0),INDEX('کارکرد اداری'!S:S,MATCH(D10,'کارکرد اداری'!C:C,0),0))} -> #N/A | M10: {=_xlfn.IFNA(INDEX('کارکرد اداری'!P:P,MATCH(C10,'کارکرد اداری'!B:B,0),0),INDEX('کارکرد اداری'!P:P,MATCH(D10,'کارکرد اداری'!C:C,0),0))} -> #N/A | N10: {=_xlfn.IFNA(INDEX('کارکرد اداری'!Q:Q,MATCH(C10,'کارکرد اداری'!B:B,0),0),INDEX('کارکرد اداری'!Q:Q,MATCH(D10,'کارکرد اداری'!C:C,0),0))} -> #N/A | O10: =$F$1-$M$1-G10-H10-I10-J10 -> #N/A | P10: =((O10*440+M10*60+N10)-(K10*60-L10))/60 -> #N/A | Q10: {=_xlfn.IFNA(INDEX(نهایی!CW:CW,MATCH(D10,نهایی!B:B,0),0)/60,INDEX(نهایی!CW:CW,MATCH(C10,نهایی!B:B,0),0)/60)} -> 151.5 | R10: =Q10-P10 -> #N/A | S10: =_xlfn.IFNA(INDEX(نهایی!CX:CX,MATCH(D10,نهایی!B:B,0)),INDEX(نهایی!CX:CX,MATCH(C10,نهایی!B:B,0))) -> 158.07805 | T10: =IF(S10>Q10,"",Q10-S10) | U10: =IF(Q10>S10,"",S10-Q10) -> 6.5780482 | V10: =IF(P10>S10,P10-S10,"") -> #N/A | W10: =IF(P10<S10,S10-P10,"") -> #N/A | X10: =ROUNDDOWN(IF((0.95-S10/P10)>0,(0.95-S10/P10),0)*Q10,0) -> #N/A | Y10: =ROUNDUP((IF(((S10/P10)-0.97)>0,((S10/P10)-0.97),0)*Q10)/1,0) -> #N/A | Z10: =VLOOKUP(C10,نهایی!B:B,1,0) -> #N/A | AA10: =VLOOKUP(D10,نهایی!B:B,1,0) -> 14760
C11: =_xlfn.XLOOKUP(D11,'کارکرد اداری'!$C$3:$C$106,'کارکرد اداری'!$B$3:$B$106,0,1) -> 317 | D11: 14331 | E11: فاطمه عالمی | G11: =_xlfn.IFNA(_xlfn.XLOOKUP(D11,'کارکرد اداری'!$C$4:$C$204,'کارکرد اداری'!$N$4:$N$204,"0",0),_xlfn.XLOOKUP(C11,'کارکرد اداری'!$C$4:$C$204,'کارکرد اداری'!$N$4:$N$204,"0",0)) -> 0 | H11: =_xlfn.XLOOKUP(D11,'کارکرد اداری'!$C$4:$C$204,'کارکرد اداری'!$K$4:$K$204,0,1) -> 0 | I11: =_xlfn.XLOOKUP(D11,'کارکرد اداری'!$C$4:$C$204,'کارکرد اداری'!$I$4:$I$204,0,1) -> 0 | J11: {=_xlfn.IFNA(INDEX('کارکرد اداری'!J:J,MATCH(C11,'کارکرد اداری'!B:B,0),0),INDEX('کارکرد اداری'!J:J,MATCH(D11,'کارکرد اداری'!C:C,0),0))} -> #N/A | K11: {=_xlfn.IFNA(INDEX('کارکرد اداری'!R:R,MATCH(C11,'کارکرد اداری'!B:B,0),0),INDEX('کارکرد اداری'!R:R,MATCH(D11,'کارکرد اداری'!C:C,0),0))} -> #N/A | L11: {=_xlfn.IFNA(INDEX('کارکرد اداری'!S:S,MATCH(C11,'کارکرد اداری'!B:B,0),0),INDEX('کارکرد اداری'!S:S,MATCH(D11,'کارکرد اداری'!C:C,0),0))} -> #N/A | M11: {=_xlfn.IFNA(INDEX('کارکرد اداری'!P:P,MATCH(C11,'کارکرد اداری'!B:B,0),0),INDEX('کارکرد اداری'!P:P,MATCH(D11,'کارکرد اداری'!C:C,0),0))} -> #N/A | N11: {=_xlfn.IFNA(INDEX('کارکرد اداری'!Q:Q,MATCH(C11,'کارکرد اداری'!B:B,0),0),INDEX('کارکرد اداری'!Q:Q,MATCH(D11,'کارکرد اداری'!C:C,0),0))} -> #N/A | O11: =$F$1-$M$1-G11-H11-I11-J11 -> #N/A | P11: =((O11*440+M11*60+N11)-(K11*60-L11))/60 -> #N/A | Q11: {=_xlfn.IFNA(INDEX(نهایی!CW:CW,MATCH(D11,نهایی!B:B,0),0)/60,INDEX(نهایی!CW:CW,MATCH(C11,نهایی!B:B,0),0)/60)} -> 166.66667 | R11: =Q11-P11 -> #N/A | S11: =_xlfn.IFNA(INDEX(نهایی!CX:CX,MATCH(D11,نهایی!B:B,0)),INDEX(نهایی!CX:CX,MATCH(C11,نهایی!B:B,0))) -> 170.97268 | T11: =IF(S11>Q11,"",Q11-S11) | U11: =IF(Q11>S11,"",S11-Q11) -> 4.3060174 | V11: =IF(P11>S11,P11-S11,"") -> #N/A | W11: =IF(P11<S11,S11-P11,"") -> #N/A | X11: =ROUNDDOWN(IF((0.95-S11/P11)>0,(0.95-S11/P11),0)*Q11,0) -> #N/A | Y11: =ROUNDUP((IF(((S11/P11)-0.97)>0,((S11/P11)-0.97),0)*Q11)/1,0) -> #N/A | Z11: =VLOOKUP(C11,نهایی!B:B,1,0) -> #N/A | AA11: =VLOOKUP(D11,نهایی!B:B,1,0) -> 14331
A12: تست | C12: =_xlfn.XLOOKUP(D12,'کارکرد اداری'!$C$3:$C$106,'کارکرد اداری'!$B$3:$B$106,0,1) -> 302 | D12: 14323 | E12: علی مرادی | G12: =_xlfn.IFNA(_xlfn.XLOOKUP(D12,'کارکرد اداری'!$C$4:$C$204,'کارکرد اداری'!$N$4:$N$204,"0",0),_xlfn.XLOOKUP(C12,'کارکرد اداری'!$C$4:$C$204,'کارکرد اداری'!$N$4:$N$204,"0",0)) -> 0 | H12: =_xlfn.XLOOKUP(D12,'کارکرد اداری'!$C$4:$C$204,'کارکرد اداری'!$K$4:$K$204,0,1) -> 0 | I12: =_xlfn.XLOOKUP(D12,'کارکرد اداری'!$C$4:$C$204,'کارکرد اداری'!$I$4:$I$204,0,1) -> 0 | J12: {=_xlfn.IFNA(INDEX('کارکرد اداری'!J:J,MATCH(C12,'کارکرد اداری'!B:B,0),0),INDEX('کارکرد اداری'!J:J,MATCH(D12,'کارکرد اداری'!C:C,0),0))} -> #N/A | K12: {=_xlfn.IFNA(INDEX('کارکرد اداری'!R:R,MATCH(C12,'کارکرد اداری'!B:B,0),0),INDEX('کارکرد اداری'!R:R,MATCH(D12,'کارکرد اداری'!C:C,0),0))} -> #N/A | L12: {=_xlfn.IFNA(INDEX('کارکرد اداری'!S:S,MATCH(C12,'کارکرد اداری'!B:B,0),0),INDEX('کارکرد اداری'!S:S,MATCH(D12,'کارکرد اداری'!C:C,0),0))} -> #N/A | M12: {=_xlfn.IFNA(INDEX('کارکرد اداری'!P:P,MATCH(C12,'کارکرد اداری'!B:B,0),0),INDEX('کارکرد اداری'!P:P,MATCH(D12,'کارکرد اداری'!C:C,0),0))} -> #N/A | N12: {=_xlfn.IFNA(INDEX('کارکرد اداری'!Q:Q,MATCH(C12,'کارکرد اداری'!B:B,0),0),INDEX('کارکرد اداری'!Q:Q,MATCH(D12,'کارکرد اداری'!C:C,0),0))} -> #N/A | O12: =$F$1-$M$1-G12-H12-I12-J12 -> #N/A | P12: =((O12*440+M12*60+N12)-(K12*60-L12))/60 -> #N/A | Q12: {=_xlfn.IFNA(INDEX(نهایی!CW:CW,MATCH(D12,نهایی!B:B,0),0)/60,INDEX(نهایی!CW:CW,MATCH(C12,نهایی!B:B,0),0)/60)} -> 135.33333 | R12: =Q12-P12 -> #N/A | S12: =_xlfn.IFNA(INDEX(نهایی!CX:CX,MATCH(D12,نهایی!B:B,0)),INDEX(نهایی!CX:CX,MATCH(C12,نهایی!B:B,0))) -> 140.80058 | T12: =IF(S12>Q12,"",Q12-S12) | U12: =IF(Q12>S12,"",S12-Q12) -> 5.4672424 | V12: =IF(P12>S12,P12-S12,"") -> #N/A | W12: =IF(P12<S12,S12-P12,"") -> #N/A | X12: =ROUNDDOWN(IF((0.95-S12/P12)>0,(0.95-S12/P12),0)*Q12,0) -> #N/A | Y12: =ROUNDUP((IF(((S12/P12)-0.97)>0,((S12/P12)-0.97),0)*Q12)/1,0) -> #N/A | Z12: =VLOOKUP(C12,نهایی!B:B,1,0) -> #N/A | AA12: =VLOOKUP(D12,نهایی!B:B,1,0) -> 14323
A13: تست | C13: =_xlfn.XLOOKUP(D13,'کارکرد اداری'!$C$3:$C$106,'کارکرد اداری'!$B$3:$B$106,0,1) -> 784 | D13: 14650 | E13: علیرضا زاهدی اره کمر | G13: =_xlfn.IFNA(_xlfn.XLOOKUP(D13,'کارکرد اداری'!$C$4:$C$204,'کارکرد اداری'!$N$4:$N$204,"0",0),_xlfn.XLOOKUP(C13,'کارکرد اداری'!$C$4:$C$204,'کارکرد اداری'!$N$4:$N$204,"0",0)) -> 0 | H13: =_xlfn.XLOOKUP(D13,'کارکرد اداری'!$C$4:$C$204,'کارکرد اداری'!$K$4:$K$204,0,1) -> 0 | I13: =_xlfn.XLOOKUP(D13,'کارکرد اداری'!$C$4:$C$204,'کارکرد اداری'!$I$4:$I$204,0,1) -> 0 | J13: {=_xlfn.IFNA(INDEX('کارکرد اداری'!J:J,MATCH(C13,'کارکرد اداری'!B:B,0),0),INDEX('کارکرد اداری'!J:J,MATCH(D13,'کارکرد اداری'!C:C,0),0))} -> #N/A | K13: {=_xlfn.IFNA(INDEX('کارکرد اداری'!R:R,MATCH(C13,'کارکرد اداری'!B:B,0),0),INDEX('کارکرد اداری'!R:R,MATCH(D13,'کارکرد اداری'!C:C,0),0))} -> #N/A | L13: {=_xlfn.IFNA(INDEX('کارکرد اداری'!S:S,MATCH(C13,'کارکرد اداری'!B:B,0),0),INDEX('کارکرد اداری'!S:S,MATCH(D13,'کارکرد اداری'!C:C,0),0))} -> #N/A | M13: {=_xlfn.IFNA(INDEX('کارکرد اداری'!P:P,MATCH(C13,'کارکرد اداری'!B:B,0),0),INDEX('کارکرد اداری'!P:P,MATCH(D13,'کارکرد اداری'!C:C,0),0))} -> #N/A | N13: {=_xlfn.IFNA(INDEX('کارکرد اداری'!Q:Q,MATCH(C13,'کارکرد اداری'!B:B,0),0),INDEX('کارکرد اداری'!Q:Q,MATCH(D13,'کارکرد اداری'!C:C,0),0))} -> #N/A | O13: =$F$1-$M$1-G13-H13-I13-J13 -> #N/A | P13: =((O13*440+M13*60+N13)-(K13*60-L13))/60 -> #N/A | Q13: {=_xlfn.IFNA(INDEX(نهایی!CW:CW,MATCH(D13,نهایی!B:B,0),0)/60,INDEX(نهایی!CW:CW,MATCH(C13,نهایی!B:B,0),0)/60)} -> 131.33333 | R13: =Q13-P13 -> #N/A | S13: =_xlfn.IFNA(INDEX(نهایی!CX:CX,MATCH(D13,نهایی!B:B,0)),INDEX(نهایی!CX:CX,MATCH(C13,نهایی!B:B,0))) -> 135.97037 | T13: =IF(S13>Q13,"",Q13-S13) | U13: =IF(Q13>S13,"",S13-Q13) -> 4.6370354 | V13: =IF(P13>S13,P13-S13,"") -> #N/A | W13: =IF(P13<S13,S13-P13,"") -> #N/A | X13: =ROUNDDOWN(IF((0.95-S13/P13)>0,(0.95-S13/P13),0)*Q13,0) -> #N/A | Y13: =ROUNDUP((IF(((S13/P13)-0.97)>0,((S13/P13)-0.97),0)*Q13)/1,0) -> #N/A | Z13: =VLOOKUP(C13,نهایی!B:B,1,0) -> 784 | AA13: =VLOOKUP(D13,نهایی!B:B,1,0) -> #N/A
C14: =_xlfn.XLOOKUP(D14,'کارکرد اداری'!$C$3:$C$106,'کارکرد اداری'!$B$3:$B$106,0,1) -> 628 | D14: 14554 | E14: الناز فرخی جعفرآبادی | G14: =_xlfn.IFNA(_xlfn.XLOOKUP(D14,'کارکرد اداری'!$C$4:$C$204,'کارکرد اداری'!$N$4:$N$204,"0",0),_xlfn.XLOOKUP(C14,'کارکرد اداری'!$C$4:$C$204,'کارکرد اداری'!$N$4:$N$204,"0",0)) -> 0 | H14: =_xlfn.XLOOKUP(D14,'کارکرد اداری'!$C$4:$C$204,'کارکرد اداری'!$K$4:$K$204,0,1) -> 0 | I14: =_xlfn.XLOOKUP(D14,'کارکرد اداری'!$C$4:$C$204,'کارکرد اداری'!$I$4:$I$204,0,1) -> 0 | J14: {=_xlfn.IFNA(INDEX('کارکرد اداری'!J:J,MATCH(C14,'کارکرد اداری'!B:B,0),0),INDEX('کارکرد اداری'!J:J,MATCH(D14,'کارکرد اداری'!C:C,0),0))} -> #N/A | K14: {=_xlfn.IFNA(INDEX('کارکرد اداری'!R:R,MATCH(C14,'کارکرد اداری'!B:B,0),0),INDEX('کارکرد اداری'!R:R,MATCH(D14,'کارکرد اداری'!C:C,0),0))} -> #N/A | L14: {=_xlfn.IFNA(INDEX('کارکرد اداری'!S:S,MATCH(C14,'کارکرد اداری'!B:B,0),0),INDEX('کارکرد اداری'!S:S,MATCH(D14,'کارکرد اداری'!C:C,0),0))} -> #N/A | M14: {=_xlfn.IFNA(INDEX('کارکرد اداری'!P:P,MATCH(C14,'کارکرد اداری'!B:B,0),0),INDEX('کارکرد اداری'!P:P,MATCH(D14,'کارکرد اداری'!C:C,0),0))} -> #N/A | N14: {=_xlfn.IFNA(INDEX('کارکرد اداری'!Q:Q,MATCH(C14,'کارکرد اداری'!B:B,0),0),INDEX('کارکرد اداری'!Q:Q,MATCH(D14,'کارکرد اداری'!C:C,0),0))} -> #N/A | O14: =$F$1-$M$1-G14-H14-I14-J14 -> #N/A | P14: =((O14*440+M14*60+N14)-(K14*60-L14))/60 -> #N/A | Q14: {=_xlfn.IFNA(INDEX(نهایی!CW:CW,MATCH(D14,نهایی!B:B,0),0)/60,INDEX(نهایی!CW:CW,MATCH(C14,نهایی!B:B,0),0)/60)} -> 147 | R14: =Q14-P14 -> #N/A | S14: =_xlfn.IFNA(INDEX(نهایی!CX:CX,MATCH(D14,نهایی!B:B,0)),INDEX(نهایی!CX:CX,MATCH(C14,نهایی!B:B,0))) -> 152.61754 | T14: =IF(S14>Q14,"",Q14-S14) | U14: =IF(Q14>S14,"",S14-Q14) -> 5.6175445 | V14: =IF(P14>S14,P14-S14,"") -> #N/A | W14: =IF(P14<S14,S14-P14,"") -> #N/A | X14: =ROUNDDOWN(IF((0.95-S14/P14)>0,(0.95-S14/P14),0)*Q14,0) -> #N/A | Y14: =ROUNDUP((IF(((S14/P14)-0.97)>0,((S14/P14)-0.97),0)*Q14)/1,0) -> #N/A | Z14: =VLOOKUP(C14,نهایی!B:B,1,0) -> #N/A | AA14: =VLOOKUP(D14,نهایی!B:B,1,0) -> 14554
C15: =_xlfn.XLOOKUP(D15,'کارکرد اداری'!$C$3:$C$106,'کارکرد اداری'!$B$3:$B$106,0,1) -> 960 | D15: 14739 | E15: عبیر البوغبیش | G15: =_xlfn.IFNA(_xlfn.XLOOKUP(D15,'کارکرد اداری'!$C$4:$C$204,'کارکرد اداری'!$N$4:$N$204,"0",0),_xlfn.XLOOKUP(C15,'کارکرد اداری'!$C$4:$C$204,'کارکرد اداری'!$N$4:$N$204,"0",0)) -> 0 | H15: =_xlfn.XLOOKUP(D15,'کارکرد اداری'!$C$4:$C$204,'کارکرد اداری'!$K$4:$K$204,0,1) -> 0 | I15: =_xlfn.XLOOKUP(D15,'کارکرد اداری'!$C$4:$C$204,'کارکرد اداری'!$I$4:$I$204,0,1) -> 0 | J15: {=_xlfn.IFNA(INDEX('کارکرد اداری'!J:J,MATCH(C15,'کارکرد اداری'!B:B,0),0),INDEX('کارکرد اداری'!J:J,MATCH(D15,'کارکرد اداری'!C:C,0),0))} -> #N/A | K15: {=_xlfn.IFNA(INDEX('کارکرد اداری'!R:R,MATCH(C15,'کارکرد اداری'!B:B,0),0),INDEX('کارکرد اداری'!R:R,MATCH(D15,'کارکرد اداری'!C:C,0),0))} -> #N/A | L15: {=_xlfn.IFNA(INDEX('کارکرد اداری'!S:S,MATCH(C15,'کارکرد اداری'!B:B,0),0),INDEX('کارکرد اداری'!S:S,MATCH(D15,'کارکرد اداری'!C:C,0),0))} -> #N/A | M15: {=_xlfn.IFNA(INDEX('کارکرد اداری'!P:P,MATCH(C15,'کارکرد اداری'!B:B,0),0),INDEX('کارکرد اداری'!P:P,MATCH(D15,'کارکرد اداری'!C:C,0),0))} -> #N/A | N15: {=_xlfn.IFNA(INDEX('کارکرد اداری'!Q:Q,MATCH(C15,'کارکرد اداری'!B:B,0),0),INDEX('کارکرد اداری'!Q:Q,MATCH(D15,'کارکرد اداری'!C:C,0),0))} -> #N/A | O15: =$F$1-$M$1-G15-H15-I15-J15 -> #N/A | P15: =((O15*440+M15*60+N15)-(K15*60-L15))/60 -> #N/A | Q15: {=_xlfn.IFNA(INDEX(نهایی!CW:CW,MATCH(D15,نهایی!B:B,0),0)/60,INDEX(نهایی!CW:CW,MATCH(C15,نهایی!B:B,0),0)/60)} -> 156.33333 | R15: =Q15-P15 -> #N/A | S15: =_xlfn.IFNA(INDEX(نهایی!CX:CX,MATCH(D15,نهایی!B:B,0)),INDEX(نهایی!CX:CX,MATCH(C15,نهایی!B:B,0))) -> 160.12519 | T15: =IF(S15>Q15,"",Q15-S15) | U15: =IF(Q15>S15,"",S15-Q15) -> 3.7918552 | V15: =IF(P15>S15,P15-S15,"") -> #N/A | W15: =IF(P15<S15,S15-P15,"") -> #N/A | X15: =ROUNDDOWN(IF((0.95-S15/P15)>0,(0.95-S15/P15),0)*Q15,0) -> #N/A | Y15: =ROUNDUP((IF(((S15/P15)-0.97)>0,((S15/P15)-0.97),0)*Q15)/1,0) -> #N/A | Z15: =VLOOKUP(C15,نهایی!B:B,1,0) -> #N/A | AA15: =VLOOKUP(D15,نهایی!B:B,1,0) -> 14739
A16: آموزشی | C16: =_xlfn.XLOOKUP(D16,'کارکرد اداری'!$C$3:$C$106,'کارکرد اداری'!$B$3:$B$106,0,1) -> 1144 | D16: 14919 | E16: جمال عربیان قره تکان | G16: =_xlfn.IFNA(_xlfn.XLOOKUP(D16,'کارکرد اداری'!$C$4:$C$204,'کارکرد اداری'!$N$4:$N$204,"0",0),_xlfn.XLOOKUP(C16,'کارکرد اداری'!$C$4:$C$204,'کارکرد اداری'!$N$4:$N$204,"0",0)) -> 0 | H16: =_xlfn.XLOOKUP(D16,'کارکرد اداری'!$C$4:$C$204,'کارکرد اداری'!$K$4:$K$204,0,1) -> 0 | I16: =_xlfn.XLOOKUP(D16,'کارکرد اداری'!$C$4:$C$204,'کارکرد اداری'!$I$4:$I$204,0,1) -> 0 | J16: {=_xlfn.IFNA(INDEX('کارکرد اداری'!J:J,MATCH(C16,'کارکرد اداری'!B:B,0),0),INDEX('کارکرد اداری'!J:J,MATCH(D16,'کارکرد اداری'!C:C,0),0))} -> #N/A | K16: {=_xlfn.IFNA(INDEX('کارکرد اداری'!R:R,MATCH(C16,'کارکرد اداری'!B:B,0),0),INDEX('کارکرد اداری'!R:R,MATCH(D16,'کارکرد اداری'!C:C,0),0))} -> #N/A | L16: {=_xlfn.IFNA(INDEX('کارکرد اداری'!S:S,MATCH(C16,'کارکرد اداری'!B:B,0),0),INDEX('کارکرد اداری'!S:S,MATCH(D16,'کارکرد اداری'!C:C,0),0))} -> #N/A | M16: {=_xlfn.IFNA(INDEX('کارکرد اداری'!P:P,MATCH(C16,'کارکرد اداری'!B:B,0),0),INDEX('کارکرد اداری'!P:P,MATCH(D16,'کارکرد اداری'!C:C,0),0))} -> #N/A | N16: {=_xlfn.IFNA(INDEX('کارکرد اداری'!Q:Q,MATCH(C16,'کارکرد اداری'!B:B,0),0),INDEX('کارکرد اداری'!Q:Q,MATCH(D16,'کارکرد اداری'!C:C,0),0))} -> #N/A | O16: =$F$1-$M$1-G16-H16-I16-J16 -> #N/A | P16: =((O16*440+M16*60+N16)-(K16*60-L16))/60 -> #N/A | Q16: {=_xlfn.IFNA(INDEX(نهایی!CW:CW,MATCH(D16,نهایی!B:B,0),0)/60,INDEX(نهایی!CW:CW,MATCH(C16,نهایی!B:B,0),0)/60)} -> 141.83333 | R16: =Q16-P16 -> #N/A | S16: =_xlfn.IFNA(INDEX(نهایی!CX:CX,MATCH(D16,نهایی!B:B,0)),INDEX(نهایی!CX:CX,MATCH(C16,نهایی!B:B,0))) -> 144.92544 | T16: =IF(S16>Q16,"",Q16-S16) | U16: =IF(Q16>S16,"",S16-Q16) -> 3.0921078 | V16: =IF(P16>S16,P16-S16,"") -> #N/A | W16: =IF(P16<S16,S16-P16,"") -> #N/A | X16: =ROUNDDOWN(IF((0.95-S16/P16)>0,(0.95-S16/P16),0)*Q16,0) -> #N/A | Y16: =ROUNDUP((IF(((S16/P16)-0.97)>0,((S16/P16)-0.97),0)*Q16)/1,0) -> #N/A | Z16: =VLOOKUP(C16,نهایی!B:B,1,0) -> 1144 | AA16: =VLOOKUP(D16,نهایی!B:B,1,0) -> #N/A
C17: =_xlfn.XLOOKUP(D17,'کارکرد اداری'!$C$3:$C$106,'کارکرد اداری'!$B$3:$B$106,0,1) -> 1121 | D17: 14900 | E17: حیدر براهولیان | G17: =_xlfn.IFNA(_xlfn.XLOOKUP(D17,'کارکرد اداری'!$C$4:$C$204,'کارکرد اداری'!$N$4:$N$204,"0",0),_xlfn.XLOOKUP(C17,'کارکرد اداری'!$C$4:$C$204,'کارکرد اداری'!$N$4:$N$204,"0",0)) -> 0 | H17: =_xlfn.XLOOKUP(D17,'کارکرد اداری'!$C$4:$C$204,'کارکرد اداری'!$K$4:$K$204,0,1) -> 0 | I17: =_xlfn.XLOOKUP(D17,'کارکرد اداری'!$C$4:$C$204,'کارکرد اداری'!$I$4:$I$204,0,1) -> 0 | J17: {=_xlfn.IFNA(INDEX('کارکرد اداری'!J:J,MATCH(C17,'کارکرد اداری'!B:B,0),0),INDEX('کارکرد اداری'!J:J,MATCH(D17,'کارکرد اداری'!C:C,0),0))} -> #N/A | K17: {=_xlfn.IFNA(INDEX('کارکرد اداری'!R:R,MATCH(C17,'کارکرد اداری'!B:B,0),0),INDEX('کارکرد اداری'!R:R,MATCH(D17,'کارکرد اداری'!C:C,0),0))} -> #N/A | L17: {=_xlfn.IFNA(INDEX('کارکرد اداری'!S:S,MATCH(C17,'کارکرد اداری'!B:B,0),0),INDEX('کارکرد اداری'!S:S,MATCH(D17,'کارکرد اداری'!C:C,0),0))} -> #N/A | M17: {=_xlfn.IFNA(INDEX('کارکرد اداری'!P:P,MATCH(C17,'کارکرد اداری'!B:B,0),0),INDEX('کارکرد اداری'!P:P,MATCH(D17,'کارکرد اداری'!C:C,0),0))} -> #N/A | N17: {=_xlfn.IFNA(INDEX('کارکرد اداری'!Q:Q,MATCH(C17,'کارکرد اداری'!B:B,0),0),INDEX('کارکرد اداری'!Q:Q,MATCH(D17,'کارکرد اداری'!C:C,0),0))} -> #N/A | O17: =$F$1-$M$1-G17-H17-I17-J17 -> #N/A | P17: =((O17*440+M17*60+N17)-(K17*60-L17))/60 -> #N/A | Q17: {=_xlfn.IFNA(INDEX(نهایی!CW:CW,MATCH(D17,نهایی!B:B,0),0)/60,INDEX(نهایی!CW:CW,MATCH(C17,نهایی!B:B,0),0)/60)} -> 102.33333 | R17: =Q17-P17 -> #N/A | S17: =_xlfn.IFNA(INDEX(نهایی!CX:CX,MATCH(D17,نهایی!B:B,0)),INDEX(نهایی!CX:CX,MATCH(C17,نهایی!B:B,0))) -> 106.72285 | T17: =IF(S17>Q17,"",Q17-S17) | U17: =IF(Q17>S17,"",S17-Q17) -> 4.3895208 | V17: =IF(P17>S17,P17-S17,"") -> #N/A | W17: =IF(P17<S17,S17-P17,"") -> #N/A | X17: =ROUNDDOWN(IF((0.95-S17/P17)>0,(0.95-S17/P17),0)*Q17,0) -> #N/A | Y17: =ROUNDUP((IF(((S17/P17)-0.97)>0,((S17/P17)-0.97),0)*Q17)/1,0) -> #N/A | Z17: =VLOOKUP(C17,نهایی!B:B,1,0) -> 1121 | AA17: =VLOOKUP(D17,نهایی!B:B,1,0) -> #N/A
B18: فیوز | C18: =_xlfn.XLOOKUP(D18,'کارکرد اداری'!$C$3:$C$106,'کارکرد اداری'!$B$3:$B$106,0,1) -> 291 | D18: 14304 | E18: مصطفی فتحی پور | G18: =_xlfn.IFNA(_xlfn.XLOOKUP(D18,'کارکرد اداری'!$C$4:$C$204,'کارکرد اداری'!$N$4:$N$204,"0",0),_xlfn.XLOOKUP(C18,'کارکرد اداری'!$C$4:$C$204,'کارکرد اداری'!$N$4:$N$204,"0",0)) -> 0 | H18: =_xlfn.XLOOKUP(D18,'کارکرد اداری'!$C$4:$C$204,'کارکرد اداری'!$K$4:$K$204,0,1) -> 0 | I18: =_xlfn.XLOOKUP(D18,'کارکرد اداری'!$C$4:$C$204,'کارکرد اداری'!$I$4:$I$204,0,1) -> 0 | J18: {=_xlfn.IFNA(INDEX('کارکرد اداری'!J:J,MATCH(C18,'کارکرد اداری'!B:B,0),0),INDEX('کارکرد اداری'!J:J,MATCH(D18,'کارکرد اداری'!C:C,0),0))} -> #N/A | K18: {=_xlfn.IFNA(INDEX('کارکرد اداری'!R:R,MATCH(C18,'کارکرد اداری'!B:B,0),0),INDEX('کارکرد اداری'!R:R,MATCH(D18,'کارکرد اداری'!C:C,0),0))} -> #N/A | L18: {=_xlfn.IFNA(INDEX('کارکرد اداری'!S:S,MATCH(C18,'کارکرد اداری'!B:B,0),0),INDEX('کارکرد اداری'!S:S,MATCH(D18,'کارکرد اداری'!C:C,0),0))} -> #N/A | M18: {=_xlfn.IFNA(INDEX('کارکرد اداری'!P:P,MATCH(C18,'کارکرد اداری'!B:B,0),0),INDEX('کارکرد اداری'!P:P,MATCH(D18,'کارکرد اداری'!C:C,0),0))} -> #N/A | N18: {=_xlfn.IFNA(INDEX('کارکرد اداری'!Q:Q,MATCH(C18,'کارکرد اداری'!B:B,0),0),INDEX('کارکرد اداری'!Q:Q,MATCH(D18,'کارکرد اداری'!C:C,0),0))} -> #N/A | O18: =$F$1-$M$1-G18-H18-I18-J18 -> #N/A | P18: =((O18*440+M18*60+N18)-(K18*60-L18))/60 -> #N/A | Q18: {=_xlfn.IFNA(INDEX(نهایی!CW:CW,MATCH(D18,نهایی!B:B,0),0)/60,INDEX(نهایی!CW:CW,MATCH(C18,نهایی!B:B,0),0)/60)} -> 148.83333 | R18: =Q18-P18 -> #N/A | S18: =_xlfn.IFNA(INDEX(نهایی!CX:CX,MATCH(D18,نهایی!B:B,0)),INDEX(نهایی!CX:CX,MATCH(C18,نهایی!B:B,0))) -> 151.07704 | T18: =IF(S18>Q18,"",Q18-S18) | U18: =IF(Q18>S18,"",S18-Q18) -> 2.2437098 | V18: =IF(P18>S18,P18-S18,"") -> #N/A | W18: =IF(P18<S18,S18-P18,"") -> #N/A | X18: =ROUNDDOWN(IF((0.95-S18/P18)>0,(0.95-S18/P18),0)*Q18,0) -> #N/A | Y18: =ROUNDUP((IF(((S18/P18)-0.97)>0,((S18/P18)-0.97),0)*Q18)/1,0) -> #N/A | Z18: =VLOOKUP(C18,نهایی!B:B,1,0) -> #N/A | AA18: =VLOOKUP(D18,نهایی!B:B,1,0) -> 14304
A19: تست | C19: =_xlfn.XLOOKUP(D19,'کارکرد اداری'!$C$3:$C$106,'کارکرد اداری'!$B$3:$B$106,0,1) -> 1066 | D19: 14865 | E19: صادق نوروزیان یدکی | G19: =_xlfn.IFNA(_xlfn.XLOOKUP(D19,'کارکرد اداری'!$C$4:$C$204,'کارکرد اداری'!$N$4:$N$204,"0",0),_xlfn.XLOOKUP(C19,'کارکرد اداری'!$C$4:$C$204,'کارکرد اداری'!$N$4:$N$204,"0",0)) -> 0 | H19: =_xlfn.XLOOKUP(D19,'کارکرد اداری'!$C$4:$C$204,'کارکرد اداری'!$K$4:$K$204,0,1) -> 0 | I19: =_xlfn.XLOOKUP(D19,'کارکرد اداری'!$C$4:$C$204,'کارکرد اداری'!$I$4:$I$204,0,1) -> 0 | J19: {=_xlfn.IFNA(INDEX('کارکرد اداری'!J:J,MATCH(C19,'کارکرد اداری'!B:B,0),0),INDEX('کارکرد اداری'!J:J,MATCH(D19,'کارکرد اداری'!C:C,0),0))} -> #N/A | K19: {=_xlfn.IFNA(INDEX('کارکرد اداری'!R:R,MATCH(C19,'کارکرد اداری'!B:B,0),0),INDEX('کارکرد اداری'!R:R,MATCH(D19,'کارکرد اداری'!C:C,0),0))} -> #N/A | L19: {=_xlfn.IFNA(INDEX('کارکرد اداری'!S:S,MATCH(C19,'کارکرد اداری'!B:B,0),0),INDEX('کارکرد اداری'!S:S,MATCH(D19,'کارکرد اداری'!C:C,0),0))} -> #N/A | M19: {=_xlfn.IFNA(INDEX('کارکرد اداری'!P:P,MATCH(C19,'کارکرد اداری'!B:B,0),0),INDEX('کارکرد اداری'!P:P,MATCH(D19,'کارکرد اداری'!C:C,0),0))} -> #N/A | N19: {=_xlfn.IFNA(INDEX('کارکرد اداری'!Q:Q,MATCH(C19,'کارکرد اداری'!B:B,0),0),INDEX('کارکرد اداری'!Q:Q,MATCH(D19,'کارکرد اداری'!C:C,0),0))} -> #N/A | O19: =$F$1-$M$1-G19-H19-I19-J19 -> #N/A | P19: =((O19*440+M19*60+N19)-(K19*60-L19))/60 -> #N/A | Q19: {=_xlfn.IFNA(INDEX(نهایی!CW:CW,MATCH(D19,نهایی!B:B,0),0)/60,INDEX(نهایی!CW:CW,MATCH(C19,نهایی!B:B,0),0)/60)} -> 129.33333 | R19: =Q19-P19 -> #N/A | S19: =_xlfn.IFNA(INDEX(نهایی!CX:CX,MATCH(D19,نهایی!B:B,0)),INDEX(نهایی!CX:CX,MATCH(C19,نهایی!B:B,0))) -> 131.40934 | T19: =IF(S19>Q19,"",Q19-S19) | U19: =IF(Q19>S19,"",S19-Q19) -> 2.0760069 | V19: =IF(P19>S19,P19-S19,"") -> #N/A | W19: =IF(P19<S19,S19-P19,"") -> #N/A | X19: =ROUNDDOWN(IF((0.95-S19/P19)>0,(0.95-S19/P19),0)*Q19,0) -> #N/A | Y19: =ROUNDUP((IF(((S19/P19)-0.97)>0,((S19/P19)-0.97),0)*Q19)/1,0) -> #N/A | Z19: =VLOOKUP(C19,نهایی!B:B,1,0) -> 1066 | AA19: =VLOOKUP(D19,نهایی!B:B,1,0) -> #N/A
C20: =_xlfn.XLOOKUP(D20,'کارکرد اداری'!$C$3:$C$106,'کارکرد اداری'!$B$3:$B$106,0,1) -> 326 | D20: 14340 | E20: رضا جعفرپور قله زو | G20: =_xlfn.IFNA(_xlfn.XLOOKUP(D20,'کارکرد اداری'!$C$4:$C$204,'کارکرد اداری'!$N$4:$N$204,"0",0),_xlfn.XLOOKUP(C20,'کارکرد اداری'!$C$4:$C$204,'کارکرد اداری'!$N$4:$N$204,"0",0)) -> 0 | H20: =_xlfn.XLOOKUP(D20,'کارکرد اداری'!$C$4:$C$204,'کارکرد اداری'!$K$4:$K$204,0,1) -> 0 | I20: =_xlfn.XLOOKUP(D20,'کارکرد اداری'!$C$4:$C$204,'کارکرد اداری'!$I$4:$I$204,0,1) -> 0 | J20: {=_xlfn.IFNA(INDEX('کارکرد اداری'!J:J,MATCH(C20,'کارکرد اداری'!B:B,0),0),INDEX('کارکرد اداری'!J:J,MATCH(D20,'کارکرد اداری'!C:C,0),0))} -> #N/A | K20: {=_xlfn.IFNA(INDEX('کارکرد اداری'!R:R,MATCH(C20,'کارکرد اداری'!B:B,0),0),INDEX('کارکرد اداری'!R:R,MATCH(D20,'کارکرد اداری'!C:C,0),0))} -> #N/A | L20: {=_xlfn.IFNA(INDEX('کارکرد اداری'!S:S,MATCH(C20,'کارکرد اداری'!B:B,0),0),INDEX('کارکرد اداری'!S:S,MATCH(D20,'کارکرد اداری'!C:C,0),0))} -> #N/A | M20: {=_xlfn.IFNA(INDEX('کارکرد اداری'!P:P,MATCH(C20,'کارکرد اداری'!B:B,0),0),INDEX('کارکرد اداری'!P:P,MATCH(D20,'کارکرد اداری'!C:C,0),0))} -> #N/A | N20: {=_xlfn.IFNA(INDEX('کارکرد اداری'!Q:Q,MATCH(C20,'کارکرد اداری'!B:B,0),0),INDEX('کارکرد اداری'!Q:Q,MATCH(D20,'کارکرد اداری'!C:C,0),0))} -> #N/A | O20: =$F$1-$M$1-G20-H20-I20-J20 -> #N/A | P20: =((O20*440+M20*60+N20)-(K20*60-L20))/60 -> #N/A | Q20: {=_xlfn.IFNA(INDEX(نهایی!CW:CW,MATCH(D20,نهایی!B:B,0),0)/60,INDEX(نهایی!CW:CW,MATCH(C20,نهایی!B:B,0),0)/60)} -> 147.33333 | R20: =Q20-P20 -> #N/A | S20: =_xlfn.IFNA(INDEX(نهایی!CX:CX,MATCH(D20,نهایی!B:B,0)),INDEX(نهایی!CX:CX,MATCH(C20,نهایی!B:B,0))) -> 149.587 | T20: =IF(S20>Q20,"",Q20-S20) | U20: =IF(Q20>S20,"",S20-Q20) -> 2.2536672 | V20: =IF(P20>S20,P20-S20,"") -> #N/A | W20: =IF(P20<S20,S20-P20,"") -> #N/A | X20: =ROUNDDOWN(IF((0.95-S20/P20)>0,(0.95-S20/P20),0)*Q20,0) -> #N/A | Y20: =ROUNDUP((IF(((S20/P20)-0.97)>0,((S20/P20)-0.97),0)*Q20)/1,0) -> #N/A | Z20: =VLOOKUP(C20,نهایی!B:B,1,0) -> #N/A | AA20: =VLOOKUP(D20,نهایی!B:B,1,0) -> 14340
C21: =_xlfn.XLOOKUP(D21,'کارکرد اداری'!$C$3:$C$106,'کارکرد اداری'!$B$3:$B$106,0,1) -> 920 | D21: 14718 | E21: مهدی خانلری ملکشاه | G21: =_xlfn.IFNA(_xlfn.XLOOKUP(D21,'کارکرد اداری'!$C$4:$C$204,'کارکرد اداری'!$N$4:$N$204,"0",0),_xlfn.XLOOKUP(C21,'کارکرد اداری'!$C$4:$C$204,'کارکرد اداری'!$N$4:$N$204,"0",0)) -> 0 | H21: =_xlfn.XLOOKUP(D21,'کارکرد اداری'!$C$4:$C$204,'کارکرد اداری'!$K$4:$K$204,0,1) -> 0 | I21: =_xlfn.XLOOKUP(D21,'کارکرد اداری'!$C$4:$C$204,'کارکرد اداری'!$I$4:$I$204,0,1) -> 0 | J21: {=_xlfn.IFNA(INDEX('کارکرد اداری'!J:J,MATCH(C21,'کارکرد اداری'!B:B,0),0),INDEX('کارکرد اداری'!J:J,MATCH(D21,'کارکرد اداری'!C:C,0),0))} -> #N/A | K21: {=_xlfn.IFNA(INDEX('کارکرد اداری'!R:R,MATCH(C21,'کارکرد اداری'!B:B,0),0),INDEX('کارکرد اداری'!R:R,MATCH(D21,'کارکرد اداری'!C:C,0),0))} -> #N/A | L21: {=_xlfn.IFNA(INDEX('کارکرد اداری'!S:S,MATCH(C21,'کارکرد اداری'!B:B,0),0),INDEX('کارکرد اداری'!S:S,MATCH(D21,'کارکرد اداری'!C:C,0),0))} -> #N/A | M21: {=_xlfn.IFNA(INDEX('کارکرد اداری'!P:P,MATCH(C21,'کارکرد اداری'!B:B,0),0),INDEX('کارکرد اداری'!P:P,MATCH(D21,'کارکرد اداری'!C:C,0),0))} -> #N/A | N21: {=_xlfn.IFNA(INDEX('کارکرد اداری'!Q:Q,MATCH(C21,'کارکرد اداری'!B:B,0),0),INDEX('کارکرد اداری'!Q:Q,MATCH(D21,'کارکرد اداری'!C:C,0),0))} -> #N/A | O21: =$F$1-$M$1-G21-H21-I21-J21 -> #N/A | P21: =((O21*440+M21*60+N21)-(K21*60-L21))/60 -> #N/A | Q21: {=_xlfn.IFNA(INDEX(نهایی!CW:CW,MATCH(D21,نهایی!B:B,0),0)/60,INDEX(نهایی!CW:CW,MATCH(C21,نهایی!B:B,0),0)/60)} -> 147.33333 | R21: =Q21-P21 -> #N/A | S21: =_xlfn.IFNA(INDEX(نهایی!CX:CX,MATCH(D21,نهایی!B:B,0)),INDEX(نهایی!CX:CX,MATCH(C21,نهایی!B:B,0))) -> 149.12389 | T21: =IF(S21>Q21,"",Q21-S21) | U21: =IF(Q21>S21,"",S21-Q21) -> 1.7905605 | V21: =IF(P21>S21,P21-S21,"") -> #N/A | W21: =IF(P21<S21,S21-P21,"") -> #N/A | X21: =ROUNDDOWN(IF((0.95-S21/P21)>0,(0.95-S21/P21),0)*Q21,0) -> #N/A | Y21: =ROUNDUP((IF(((S21/P21)-0.97)>0,((S21/P21)-0.97),0)*Q21)/1,0) -> #N/A | Z21: =VLOOKUP(C21,نهایی!B:B,1,0) -> #N/A | AA21: =VLOOKUP(D21,نهایی!B:B,1,0) -> 14718
A22: خدمات پس از فروش | C22: =_xlfn.XLOOKUP(D22,'کارکرد اداری'!$C$3:$C$106,'کارکرد اداری'!$B$3:$B$106,0,1) -> 709 | D22: 14140 | E22: مرضیه تقوی | G22: =_xlfn.IFNA(_xlfn.XLOOKUP(D22,'کارکرد اداری'!$C$4:$C$204,'کارکرد اداری'!$N$4:$N$204,"0",0),_xlfn.XLOOKUP(C22,'کارکرد اداری'!$C$4:$C$204,'کارکرد اداری'!$N$4:$N$204,"0",0)) -> 0 | H22: =_xlfn.XLOOKUP(D22,'کارکرد اداری'!$C$4:$C$204,'کارکرد اداری'!$K$4:$K$204,0,1) -> 0 | I22: =_xlfn.XLOOKUP(D22,'کارکرد اداری'!$C$4:$C$204,'کارکرد اداری'!$I$4:$I$204,0,1) -> 0 | J22: {=_xlfn.IFNA(INDEX('کارکرد اداری'!J:J,MATCH(C22,'کارکرد اداری'!B:B,0),0),INDEX('کارکرد اداری'!J:J,MATCH(D22,'کارکرد اداری'!C:C,0),0))} -> #N/A | K22: {=_xlfn.IFNA(INDEX('کارکرد اداری'!R:R,MATCH(C22,'کارکرد اداری'!B:B,0),0),INDEX('کارکرد اداری'!R:R,MATCH(D22,'کارکرد اداری'!C:C,0),0))} -> #N/A | L22: {=_xlfn.IFNA(INDEX('کارکرد اداری'!S:S,MATCH(C22,'کارکرد اداری'!B:B,0),0),INDEX('کارکرد اداری'!S:S,MATCH(D22,'کارکرد اداری'!C:C,0),0))} -> #N/A | M22: {=_xlfn.IFNA(INDEX('کارکرد اداری'!P:P,MATCH(C22,'کارکرد اداری'!B:B,0),0),INDEX('کارکرد اداری'!P:P,MATCH(D22,'کارکرد اداری'!C:C,0),0))} -> #N/A | N22: {=_xlfn.IFNA(INDEX('کارکرد اداری'!Q:Q,MATCH(C22,'کارکرد اداری'!B:B,0),0),INDEX('کارکرد اداری'!Q:Q,MATCH(D22,'کارکرد اداری'!C:C,0),0))} -> #N/A | O22: =$F$1-$M$1-G22-H22-I22-J22 -> #N/A | P22: =((O22*440+M22*60+N22)-(K22*60-L22))/60 -> #N/A | Q22: {=_xlfn.IFNA(INDEX(نهایی!CW:CW,MATCH(D22,نهایی!B:B,0),0)/60,INDEX(نهایی!CW:CW,MATCH(C22,نهایی!B:B,0),0)/60)} -> 178.33333 | R22: =Q22-P22 -> #N/A | S22: =_xlfn.IFNA(INDEX(نهایی!CX:CX,MATCH(D22,نهایی!B:B,0)),INDEX(نهایی!CX:CX,MATCH(C22,نهایی!B:B,0))) -> 179.30392 | T22: =IF(S22>Q22,"",Q22-S22) | U22: =IF(Q22>S22,"",S22-Q22) -> 0.97058824 | V22: =IF(P22>S22,P22-S22,"") -> #N/A | W22: =IF(P22<S22,S22-P22,"") -> #N/A | X22: =ROUNDDOWN(IF((0.95-S22/P22)>0,(0.95-S22/P22),0)*Q22,0) -> #N/A | Y22: =ROUNDUP((IF(((S22/P22)-0.97)>0,((S22/P22)-0.97),0)*Q22)/1,0) -> #N/A | Z22: =VLOOKUP(C22,نهایی!B:B,1,0) -> #N/A | AA22: =VLOOKUP(D22,نهایی!B:B,1,0) -> 14140
