Workbook
Name _Hlk327020827: 'SEFARESH TOLID'!$B$41

Sheet base
A1: کد کالا (انبار 3) | B1: کد کالا (انبار4) | C1: Ref. No. | D1: نوع کلید مینیاتوری | E1: کد جدید کالا | F1: ضریب | G1: اصطلاح در بازار | H1: تعداد در کارتن
A2: 331150101 | C2: 566501 | D2: EP61 B06 | E2: 330000146 | F2: 1 | G2: کلید مینیاتوری تک فاز 06آمپر تیپB (10 KA) | H2: 120 | J2: ردیف | K2: نام فروشگاه | L2: مدیریت فروشگاه | M2: آدرس | N2: تلفن | O2: شماره اقتصادی | P2: کد عاملیت
A3: 331150102 | C3: 566502 | D3: EP61 B10 | E3: 330000148 | F3: 1 | G3: کلید مینیاتوری تک فاز 10 آمپر تیپ B (10 KA) | H3: 120 | J3: 1 | K3: الکترو آ.ا.گ - تهران | L3: کریمی | M3: تهران - خیابان لاله زار جنوبی- پاساژ ادیسون پلاک 1 | N3: 021-33111679 | O3: 4280386862 | P3: 13335
A4: 331150103 | C4: 566503 | D4: EP61 B16 | E4: 330000150 | F4: 1 | G4: کلید مینیاتوری تک فاز16 آمپر تیپ B (10 KA) | H4: 120 | J4: 2 | K4: الکترو آ.ا.گ - اهواز | L4: منجزی | M4: اهواز - خیابان طالقانی - بین نظامی و فردوسی- جنب پاساژ برق | N4: 061-32216147-32233186-7 | O4: 1971490441 | P4: 13499
A5: 331150104 | C5: 566504 | D5: EP61 B20 | E5: 330000152 | F5: 1 | G5: کلید مینیاتوری تک فاز20 آمپر تیپ B (10 KA) | H5: 120 | J5: 3 | K5: الکتروسهیل - مشهد | L5: قائمی | M5: مشهد - خیابان آخوند خراسانی- آخوند خراسانی 10 - جنب بانک ملی - شماره 940/2 | N5: 051-32255416 | O5: 938604023 | P5: 13937
A6: 331150105 | C6: 566505 | D6: EP61 B25 | E6: 330000154 | F6: 1 | G6: کلید مینیاتوری تک فاز25 آمپر تیپ B (10 KA) | H6: 120 | J6: 4 | K6: خانه برق ایمن-قم | L6: اروجلو | M6: قم -بلوار شهید صدوقی -خیابان عطاران -ابتدای کوچه 10 -ساختمان تسنیم واحد 4 کدپستی :3716669166 | N6: 025-32944718 | O6: 5719117202 | P6: 13818
A7: 331150106 | C7: 566506 | D7: EP61 B32 | E7: 330000156 | F7: 1 | G7: کلید مینیاتوری تک فاز32 آمپر تیپ B (10 KA) | H7: 120 | J7: 5 | K7: خیام الکتریک -سنندج | L7: محمدی | M7: سنندج -چهارراه شهدا - ابتدای خیابان 17 شهریور - پلاک 109 | N7: 087- 33170220-33170111 | O7: 6469508464 | P7: 13392
A8: 331150107 | C8: 566507 | D8: EP61 B40 | E8: 330000158 | F8: 1 | G8: کلید مینیاتوری تک فاز40 آمپر تیپ B (10 KA) | H8: 120 | J8: 6 | K8: کالای برق عسکری-رشت | L8: عسکری | M8: رشت - فلکه گاز- مقابل آپارتمان های رامیرزا | N8: 013-33471780 | O8: 2594067423 | P8: 13383
A9: 331150117 | C9: 566508 | D9: EP61 B50 | E9: 330000160 | F9: 1 | G9: کلید مینیاتوری تک فاز50 آمپر تیپ B (10 KA) | H9: 120 | J9: 7 | K9: کالای برق ولیعصر-شیراز | L9: مصلح | M9: شیراز - خیابان قاآنی شمالی 4 | N9: 071-32362725 | O9: 5139827166 | P9: 13760
A10: 331150118 | C10: 566509 | D10: EP61 B63 | E10: 330000162 | F10: 1 | G10: کلید مینیاتوری تک فاز63 آمپر تیپ B (10 KA) | H10: 120 | K10: کالای برق ولیعصر-شیراز | L10: مصلح | M10: شیراز - خیابان قاآنی شمالی 5 | N10: 071-32362725 | O10: 5139827166 | P10: 132345
A11: 331150108 | C11: 566515 | D11: EP61 C06 | E11: 330000182 | F11: 1 | G11: کلید مینیاتوری تک فاز06 آمپر تیپ C (10 KA) | H11: 120 | K11: کالای برق ولیعصر-شیراز | L11: مصلح | M11: شیراز - خیابان قاآنی شمالی 6 | N11: 071-32362725 | O11: 5139827166 | P11: 132346
A12: 331150109 | B12: 441150109 | C12: 566516 | D12: EP61 C10 | E12: 330000165 | F12: 1 | G12: کلید مینیاتوری تک فاز10 آمپر تیپ C (10 KA) | H12: 120 | J12: 8 | K12: پدیده برق و صنعت-تهران | L12: فرهنگی | M12: تهران - خیابان لاله زار جنوبی- پاساژ بهار - طبقه دوم - پلاک 3/22 | N12: 021-33938078 | O12: 76024105 | P12: 33230
A13: 331150110 | C13: 566517 | D13: EP61 C16 | E13: 330000167 | F13: 1 | G13: کلید مینیاتوری تک فاز16 آمپر تیپ C (10 KA) | H13: 120 | J13: 9 | K13: صنایع برق موسوی -کرمانشاه | L13: موسوی | M13: کرمانشاه - میدان جوانشیر-خیابان کوهساری | N13: 083-37215080 | O13: 3256471201 | P13: 13417
A14: 331150111 | C14: 566518 | D14: EP61 C20 | E14: 330000170 | F14: 1 | G14: کلید مینیاتوری تک فاز20 آمپر تیپ C (10 KA) | H14: 120 | J14: 10 | K14: کالای برق نیرو-لرستان | L14: سلیمانی | M14: لرستان - بروجرد -خیابان حافظ شمالی - پلاک 145 | N14: 066 - 42623599 | O14: 4132032655 | P14: 13440
A15: 331150112 | B15: 441150112 | C15: 566519 | D15: EP61 C25 | E15: 330000172 | F15: 1 | G15: کلید مینیاتوری تک فاز25 آمپر تیپ C (10 KA) | H15: 120 | J15: 11 | K15: الکتروفاز -مازندران | L15: مطلبی | M15: ساری- خیابان خیام- جنب آب و فاضلاب روستایی استان | N15: 011-33245364 - 33247364 | O15: 2090199318 | P15: 13444
A16: 331150113 | B16: 441150113 | C16: 566520 | D16: EP61 C32 | E16: 330000175 | F16: 1 | G16: کلید مینیاتوری تک فاز32 آمپر تیپ C (10 KA) | H16: 120 | J16: 12 | K16: بازرگانی مدار صفر درجه شمال(کالای برق ترابی) | L16: ترابی | M16: ساری -کمربندی جنوبی، بلوار سلیم بهرامی، نبش سلیم بهرام 16 | N16: 011-33600000 | O16: 2093482428 | P16: 13299
A17: 331150114 | C17: 566521 | D17: EP61 C40 | E17: 330000178 | F17: 1 | G17: کلید مینیاتوری تک فاز40 آمپر تیپ C (10 KA) | H17: 120 | K17: بازرگانی مدار صفر درجه شمال(کالای برق ترابی) | L17: ترابی | M17: ساری -کمربندی جنوبی، بلوار سلیم بهرامی، نبش سلیم بهرام 17 | N17: 011-3360000 | O17: 2093482428 | P17: 132348
A18: 331150115 | C18: 566522 | D18: EP61 C50 | E18: 330000180 | F18: 1 | G18: کلید مینیاتوری تک فاز50 آمپر تیپ C (10 KA) | H18: 120 | J18: 13 | K18: کرمان تامین نیرو-کرمان | L18: فردوسی پور | M18: کرمان - خیابان آیت الله صالحی - حدفاصل کوچه 10 و 12 | N18: 034-32528417-32531153 | O18: 2992841846 | P18: 13955
A19: 331150116 | C19: 566523 | D19: EP61 C63 | E19: 330000184 | F19: 1 | G19: کلید مینیاتوری تک فاز63 آمپر تیپ C (10 KA) | H19: 120 | J19: 14 | K19: فروشگاه ایمن رعد-زاهدان | L19: زینلی | M19: زاهدان- خیابان امام خمینی غربی- نرسیده به آتش نشانی- روبروی امام خمینی 57 | N19: 054-33213617 | O19: 3050580811 | P19: 13470
A20: مجموع EP61 : | J20: 15 | K20: کالای برق فلسطین-گلستان | L20: توپکانلو | M20: گرگان- خیابان شهید بهشتی- 15 متری مهرآیین | N20: 017-32233632 | O20: 2121544305 | P20: 13457
A21: 332160120 | C21: 566541 | D21: EP62 B06 | E21: 330000186 | F21: 2 | G21: کلید مینیاتوری دو فاز06 آمپر تیپ B (10 KA) | H21: 60 | J21: 16 | K21: کالا ی برق خسرو-مازندران | L21: مهدوی | M21: بابل- اتوبان بابل _ آمل-نرسیده به پلیس راه بابل - ساختمان شمس | N21: 011-32277674 | O21: 2062902786 | P21: 13604
A22: 332160123 | C22: 566542 | D22: EP62 B10 | E22: - | F22: 2 | G22: کلید مینیاتوری دو فاز10 آمپر تیپ B (10 KA) | H22: 60 | J22: 17 | K22: کالای برق گرمانور-زنجان | L22: کاظمی | M22: زنجان- خبابان امام - کوچه باشگاه- روبروی بانک رفاه- الکتریکی گرمانور | N22: 024-33363532 | O22: 4281398821 | P22: 13705
A23: 332160118 | C23: 566544 | D23: EP62 B16 | E23: 330000188 | F23: 2 | G23: کلید مینیاتوری دو فاز16 آمپر تیپ B (10 KA) | H23: 60 | J23: 18 | K23: الکتروپروتون-زنجان | L23: محرمی | M23: زنجان -کوچه باشگاه- پاساژ کسری- پلاک 3 کد پستی 4517617117 | N23: 024-33336771 | O23: 4280911511 | P23: 13325
A24: 332160124 | C24: 566545 | D24: EP62 B20 | E24: 330000189 | F24: 2 | G24: کلید مینیاتوری دو فاز20 آمپر تیپ B (10 KA) | H24: 60 | J24: 19 | K24: فروشگاه RI2 | L24: سلیمی-عطایی | M24: تهران- لاله زار نو (شمالی )-مجتمع تجاری البرز 20 شماره 102 | N24: 021-66341442 | O24: 69492980 | P24: 131732
A25: 332160119 | C25: 566546 | D25: EP62 B25 | E25: 330000190 | F25: 2 | G25: کلید مینیاتوری دو فاز25 آمپر تیپ B (10 KA) | H25: 60 | J25: 20 | K25: کالای برق فراهانی | L25: ایمان فراهانی | M25: اراک- خیابان مشهد ۵۰ متر بعد از پمپ بنزین نرسیده به لعلی | N25: 086-34255880-1 | O25: 521124867 | P25: 132520
A26: 332160135 | C26: 566547 | D26: EP62 B32 | E26: 330000191 | F26: 2 | G26: کلید مینیاتوری دو فاز32 آمپر تیپ B (10 KA) | H26: 60 | J26: 21 | K26: کالای برق اسرام | L26: کلاته | M26: بجنورد - خیابان شهید بهشتی جنوبی - جنب کوچه سعدی کالای برق اسرام | N26: 09153841431 | O26: 651736919 | P26: 131809
A27: 332160131 | C27: 566548 | D27: EP62 B40 | E27: 330000192 | F27: 2 | G27: کلید مینیاتوری دو فاز40 آمپر تیپ B (10 KA) | H27: 60 | J27: 22 | K27: نیک اندیشان نوین | L27: نصیری | M27: تهران- میدان امام خمینی- خیابان لاله زار جنوبی- کوچه بوشهری ،پاساژ تهران الکتریک ،طبقه اول ،پلاک 226 | N27: 09124454952 | O27: 41154176479 | P27: 131692
A28: 332160132 | C28: 566549 | D28: EP62 B50 | E28: - | F28: 2 | G28: کلید مینیاتوری دو فاز50 آمپر تیپ B (10 KA) | H28: 60 | J28: 23 | K28: فروشگاه برق اسپادانا | L28: ربیعی | M28: اصفهان – خیابان فردوسی-جنب بن بست 19 - برق اسپادانا | N28: 031-32246465 | O28: 1270838083 | P28: 132259
A29: 332160129 | C29: 566550 | D29: EP62 B63 | E29: - | F29: 2 | G29: کلید مینیاتوری دو فاز63 آمپر تیپ B (10 KA) | H29: 60 | K29: فروشگاه برق اسپادانا | L29: ربیعی | M29: اصفهان – خیابان فردوسی-جنب بن بست 19 - برق اسپادانا | N29: 031-32246465 | O29: 1270838083 | P29: 131911
A30: 332160122 | C30: 566556 | D30: EP62 C06 | E30: 330000193 | F30: 2 | G30: کلید مینیاتوری دو فاز06 آمپر تیپ C (10 KA) | H30: 60 | J30: 24 | K30: رامین تجارت گستران پارس نور | L30: رضامند | M30: مشهد - خیابان اخوند خراسانی -بین آخوند خراسانی 7 و9-پلاک 9/9 | N30: 051-32258500 | O30: 411488338886 | P30: 131946
A31: 332160128 | C31: 566557 | D31: EP62 C10 | E31: 330000195 | F31: 2 | G31: کلید مینیاتوری دو فاز10 آمپر تیپ C (10 KA) | H31: 60 | J31: 25 | K31: کالای برق و لوسترخیربین | L31: خیربین | M31: بیرجند-خیابان شهید بهشتی -بهشتی 19- کالای برق و لوستر خیربین | N31: 056-32403502 | O31: 653300956 | P31: 131808
A32: 332160117 | C32: 566559 | D32: EP62 C16 | E32: 330000196 | F32: 2 | G32: کلید مینیاتوری دو فاز16 آمپر تیپ C (10 KA) | H32: 60 | J32: 26 | K32: کالای برق سعید | L32: عابدینی | M32: قزوین - خیابان سعدی -چهار راه نظام وفا به طرف بازار - مقابل بانک تجارت | N32: 028-33229771 | O32: 4320665422 | P32: 131901
A33: 332160133 | C33: 566560 | D33: EP62 C20 | E33: 330000197 | F33: 2 | G33: کلید مینیاتوری دو فاز20 آمپر تیپ C (10 KA) | H33: 60 | J33: 27 | K33: شایان برق هرمز | L33: فرهادی | M33: بندر عباس -خیابان کارگزاری - پشت مبل گله داری - فروشگاه شایان برق هرمز | N33: 076-32214042 | O33: 411544894683 | P33: 131660
A34: 332160115 | C34: 566561 | D34: EP62 C25 | E34: 330000198 | F34: 2 | G34: کلید مینیاتوری دو فاز25 آمپر تیپ C (10 KA) | H34: 60 | J34: 28 | K34: کالای برق یزد الکتریک | L34: پوریوسفی | M34: کرج - خیابان شهید بهشتی -حدفاصل سه راهی گوهر دشت و دهقان ویلا -جنب بانک سپه | N34: 026-34468315 | O34: 44323485801 | P34: 131871
A35: 332160116 | C35: 566562 | D35: EP62 C32 | E35: 330000199 | F35: 2 | G35: کلید مینیاتوری دو فاز32 آمپر تیپ C (10 KA) | H35: 60 | J35: 29 | K35: کالای برق آرتیمان | L35: امینی | M35: مازندران - آمل -میدان قائم -بعد از پمپ بنزین - روبروی آفتاب 56 - پلاک 110 | N35: 011-44234742-4 | O35: 2140250303 | P35: 131974
A36: 332160121 | C36: 566563 | D36: EP62 C40 | E36: 330000200 | F36: 2 | G36: کلید مینیاتوری دو فاز40 آمپر تیپ C (10 KA) | H36: 60 | J36: 30 | K36: الکتروتکنیک ارگ قدرت | L36: سیدین | M36: تبریز - خیابان فردوسی - ابتدای خیابان امین -جنب باربری لوان تور | N36: 041-35544797 | O36: 1360822194 | P36: 131973
A37: 332160136 | C37: 566564 | D37: EP62 C50 | E37: 330000201 | F37: 2 | G37: کلید مینیاتوری دو فاز50 آمپر تیپ C (10 KA) | H37: 60 | J37: 31 | K37: کالای برق مناف زاده | L37: مناف زاده | M37: اردبیل - خیابان جمهوری -کالای برق مناف زاده | N37: 045-33334834 | O37: 1465790705 | P37: 132006
A38: 332160130 | C38: 566565 | D38: EP62 C63 | E38: 330000202 | F38: 2 | G38: کلید مینیاتوری دو فاز63 آمپر تیپ C (10 KA) | H38: 60 | J38: 32 | K38: کویر صنعت یگانه | L38: یگانه فرد | M38: یزد-بلوارجمهوری-روبروی درب کارخانه افشار- ساختمان یگانه | N38: 035-35228852 | O38: 4430601992 | P38: 132304
A39: مجموع EP62 : | K39: کویر صنعت یگانه | L39: یگانه فرد | M39: یزد-بلوارجمهوری-روبروی درب کارخانه افشار- ساختمان یگانه | N39: 035-35228852 | O39: 4430601992 | P39: 13310
A40: 333170101 | C40: 566581 | D40: EP63 B06 | E40: 330000203 | F40: 3 | G40: کلید مینیاتوری سه فاز06 آمپر تیپ B (10 KA) | H40: 40 | J40: 33 | K40: الکترو تابناک | L40: برزگر | M40: تبریز -خیابان فردوسی روبروی سرای نصیرزاده - پلاک 203 | N40: 041-35550174 | O40: 1375784528 | P40: 13700
...

Sheet SEFARESH TOLID
B2: عنوان سند: ثبت سفارش مشتری
B3: تاریخ : | C3: چهارشنبه 29 مرداد 1404 | E3: شماره سریال : | I3: نام مشتری : | K3: مهرداد مصلح - ولیعصر
B4: آدرس مشتری : | D4: شیراز-خیابان قاآنی شمالی روبری خیابان منوچهری | L4: کد تفصیلی : | M4: 132556
B5: کد اقتصادی / کد ملی مشتری : | D5: 2300803992 | E5: 2300803992 | I5: تلفن مشتری : | K5: 07191004455
B6: نوع امکان سنجی : | D6: محصول جدید | E6: محصول با سابقه قبلی | G6: شرکت درمناقصه | J6: نمونه | L6: سایر: ....................
B7: ردیف | C7: کد محصول | D7: کد مرجع | E7: نام محصول | F7: تعداد | G7: تاریخ نیازمشتری | J7: تاریخ امکان سنجی و ارسال | L7: توضیحات
B8: 1
B9: 2
B10: 3
B11: 4
B12: 5
B13: 6
B14: 7
B15: 8
B16: 9
B17: 10
B18: 11
B19: 12
... B35: 28
B36: 29 | D36: =IFERROR(INDEX(base!C:C,MATCH('SEFARESH TOLID'!E36,base!D:D,)),0) -> 0
B37: 30 | D37: =IFERROR(INDEX(base!C:C,MATCH('SEFARESH TOLID'!E37,base!D:D,)),0) -> 0
B38: 31 | D38: =IFERROR(INDEX(base!C:C,MATCH('SEFARESH TOLID'!E38,base!D:D,)),0) -> 0
B39: 32 | D39: =IFERROR(INDEX(base!C:C,MATCH('SEFARESH TOLID'!E39,base!D:D,)),0) -> 0
B40: 33 | D40: =IFERROR(INDEX(base!C:C,MATCH('SEFARESH TOLID'!E40,base!D:D,)),0) -> 0
B41: 34 | C41: {=IFERROR(INDEX(base!E:E,+MATCH('SEFARESH TOLID'!E41,base!D:D,0)),0)} -> 0 | D41: =IFERROR(INDEX(base!C:C,MATCH('SEFARESH TOLID'!E41,base!D:D,)),0) -> 0 | E41: =IFERROR(INDEX(base!D:D,MATCH(#REF!,base!G:G,0)),0) -> 0
B42: 35 | C42: {=IFERROR(INDEX(base!E:E,+MATCH('SEFARESH TOLID'!E42,base!D:D,0)),0)} -> 0 | D42: =IFERROR(INDEX(base!C:C,MATCH('SEFARESH TOLID'!E42,base!D:D,)),0) -> 0 | E42: =IFERROR(INDEX(base!D:D,MATCH(#REF!,base!G:G,0)),0) -> 0
B43: 36 | C43: {=IFERROR(INDEX(base!E:E,+MATCH('SEFARESH TOLID'!E43,base!D:D,0)),0)} -> 0 | D43: =IFERROR(INDEX(base!C:C,MATCH('SEFARESH TOLID'!E43,base!D:D,)),0) -> 0 | E43: =IFERROR(INDEX(base!D:D,MATCH(#REF!,base!G:G,0)),0) -> 0
B44: 37 | C44: {=IFERROR(INDEX(base!E:E,+MATCH('SEFARESH TOLID'!E44,base!D:D,0)),0)} -> 0 | D44: =IFERROR(INDEX(base!C:C,MATCH('SEFARESH TOLID'!E44,base!D:D,)),0) -> 0 | E44: =IFERROR(INDEX(base!D:D,MATCH(#REF!,base!G:G,0)),0) -> 0
B45: 38 | C45: {=IFERROR(INDEX(base!E:E,+MATCH('SEFARESH TOLID'!E45,base!D:D,0)),0)} -> 0 | D45: =IFERROR(INDEX(base!C:C,MATCH('SEFARESH TOLID'!E45,base!D:D,)),0) -> 0 | E45: =IFERROR(INDEX(base!D:D,MATCH(#REF!,base!G:G,0)),0) -> 0
B46: 39 | C46: {=IFERROR(INDEX(base!E:E,+MATCH('SEFARESH TOLID'!E46,base!D:D,0)),0)} -> 0 | D46: =IFERROR(INDEX(base!C:C,MATCH('SEFARESH TOLID'!E46,base!D:D,)),0) -> 0 | E46: =IFERROR(INDEX(base!D:D,MATCH(#REF!,base!G:G,0)),0) -> 0
B47: 40 | C47: {=IFERROR(INDEX(base!E:E,+MATCH('SEFARESH TOLID'!E47,base!D:D,0)),0)} -> 0 | D47: =IFERROR(INDEX(base!C:C,MATCH('SEFARESH TOLID'!E47,base!D:D,)),0) -> 0 | E47: =IFERROR(INDEX(base!D:D,MATCH(#REF!,base!G:G,0)),0) -> 0
B48: « توجه : این قسمت توسط واحد فروش قبل از ارسال فرم به واحد برنامه ریزی تکمیل گردد . »
B49: اطلاعات و مشخصات فنی محصول درخواست شده توسط مشتری :
B50: آیا محصول مذکور دارای آرم یا نام دلخواه مشتری می باشد که برروی محصول حک شود؟ بله خیر کدام آرم / نام ؟ ........................................
B51: شرایط مونتاژ محصول : به طور مثال : مونتاژ با کنتور مونتاژ بدون کنتور
B52: سایر موارد : .........................................................................................................................................................................................................................................................
B53: «درصورت نمونه بودن ، قسمت زیرپس از تولید محصول توسط واحدهای تولید ،فنی مهندسی و کنترل کیفیت تایید گردد.»
B54: تایید واحد تولید : تایید واحد فنی مهندسی : تایید واحد کنترل کیفیت :
B55: « درصورتی که محصول کنتور هوشمند باشد ،تایید نهایی توسط واحدR&D الزامی است » تایید واحد R&D :
B56: 1- نتیجه امکان سنجی و ارسال به این شرح میباشد : سرپرست برنامه ریزی تاریخ : OK NOT OK
...
